INFO:Calentando motores...
INFO:[13/Jun/2016:17:03:52] ENGINE Bus STARTING
INFO:[13/Jun/2016:17:03:52] ENGINE Started monitor thread '_TimeoutMonitor'.
INFO:[13/Jun/2016:17:03:52] ENGINE Started monitor thread 'Autoreloader'.
INFO:[13/Jun/2016:17:03:52] ENGINE Serving on http://0.0.0.0:5432
INFO:[13/Jun/2016:17:03:52] ENGINE Bus STARTED
INFO:Join entre tweets...
INFO:[13/Jun/2016:17:10:08] ENGINE Restarting because /home/jduarte/Workspace/TesisSpark/tools.py changed.
INFO:[13/Jun/2016:17:10:08] ENGINE Stopped thread 'Autoreloader'.
INFO:[13/Jun/2016:17:10:08] ENGINE Bus STOPPING
INFO:[13/Jun/2016:17:10:08] ENGINE HTTP Server cherrypy._cpwsgi_server.CPWSGIServer(('0.0.0.0', 5432)) shut down
INFO:[13/Jun/2016:17:10:08] ENGINE Stopped thread '_TimeoutMonitor'.
INFO:[13/Jun/2016:17:10:08] ENGINE Bus STOPPED
INFO:[13/Jun/2016:17:10:08] ENGINE Bus EXITING
INFO:[13/Jun/2016:17:10:08] ENGINE Bus EXITED
INFO:[13/Jun/2016:17:10:08] ENGINE Waiting for child threads to terminate...
INFO:[13/Jun/2016:17:10:08] ENGINE Re-spawning /home/jduarte/Workspace/TesisSpark/server.py
INFO:Calentando motores...
INFO:[13/Jun/2016:17:13:25] ENGINE Bus STARTING
INFO:[13/Jun/2016:17:13:25] ENGINE Started monitor thread '_TimeoutMonitor'.
INFO:[13/Jun/2016:17:13:25] ENGINE Started monitor thread 'Autoreloader'.
INFO:[13/Jun/2016:17:13:25] ENGINE Serving on http://0.0.0.0:5432
INFO:[13/Jun/2016:17:13:25] ENGINE Bus STARTED
INFO:Cargando timelines...
INFO:Calculando features para tweets...
INFO:Iniciando calculo de tweets por dia...
INFO:Iniciando calculo de tweets por hora...
INFO:Iniciando exploracion de las fuentes de los tweets...
INFO:Iniciando calculo de diversidad lexicografica...
INFO:Iniciando calculo del promedio de la longuitud de los tweets...
INFO:Iniciando calculo del ratio de respuestas...
INFO:Iniciando calculo del promedio de los hashtags...
INFO:Iniciando calculo del promedio de menciones...
INFO:Iniciando calculo del promedio de palabras por tweet...
INFO:Iniciando calculo del promedio de diversidad de palabras...
INFO:[13/Jun/2016:17:14:15] ENGINE Restarting because /home/jduarte/Workspace/TesisSpark/app.py changed.
INFO:[13/Jun/2016:17:14:15] ENGINE Stopped thread 'Autoreloader'.
INFO:[13/Jun/2016:17:14:15] ENGINE Bus STOPPING
INFO:Iniciando calculo del ratio de urls...
INFO:Registrando tablas...
INFO:Join entre tweets...
INFO:Calculando features para usuarios...
INFO:Realizando join de usuarios con tweets...
INFO:Finalizado el join...
INFO:[13/Jun/2016:17:14:44] ENGINE HTTP Server cherrypy._cpwsgi_server.CPWSGIServer(('0.0.0.0', 5432)) shut down
INFO:[13/Jun/2016:17:14:44] ENGINE Stopped thread '_TimeoutMonitor'.
INFO:[13/Jun/2016:17:14:44] ENGINE Bus STOPPED
INFO:[13/Jun/2016:17:14:44] ENGINE Bus EXITING
INFO:[13/Jun/2016:17:14:44] ENGINE Bus EXITED
INFO:[13/Jun/2016:17:14:44] ENGINE Waiting for child threads to terminate...
INFO:[13/Jun/2016:17:14:44] ENGINE Re-spawning /home/jduarte/Workspace/TesisSpark/server.py
INFO:Calentando motores...
INFO:[13/Jun/2016:17:27:06] ENGINE Bus STARTING
INFO:[13/Jun/2016:17:27:06] ENGINE Started monitor thread '_TimeoutMonitor'.
INFO:[13/Jun/2016:17:27:06] ENGINE Started monitor thread 'Autoreloader'.
INFO:[13/Jun/2016:17:27:06] ENGINE Serving on http://0.0.0.0:5432
INFO:[13/Jun/2016:17:27:06] ENGINE Bus STARTED
INFO:{u'humano': u'/home/jduarte/Workspace/datos/datos_cat/humano', u'ciborg': u'/home/jduarte/Workspace/datos/datos_cat/ciborg', u'bot': u'/home/jduarte/Workspace/datos/datos_cat/bot'}
INFO:Cargando timelines...
INFO:Calculo de features en tweetsRDD_humanos...
INFO:Calculando features para tweets...
INFO:Iniciando calculo de tweets por dia...
INFO:Iniciando calculo de tweets por hora...
INFO:Iniciando exploracion de las fuentes de los tweets...
INFO:Iniciando calculo de diversidad lexicografica...
INFO:Iniciando calculo del promedio de la longuitud de los tweets...
INFO:Iniciando calculo del ratio de respuestas...
INFO:Iniciando calculo del promedio de los hashtags...
INFO:Iniciando calculo del promedio de menciones...
INFO:Iniciando calculo del promedio de palabras por tweet...
INFO:Iniciando calculo del promedio de diversidad de palabras...
INFO:Iniciando calculo del ratio de urls...
INFO:Registrando tablas...
INFO:Join entre tweets...
INFO:Calculo de features en tweetsRDD_bots...
INFO:Calculando features para tweets...
INFO:Iniciando calculo de tweets por dia...
INFO:Iniciando calculo de tweets por hora...
INFO:Iniciando exploracion de las fuentes de los tweets...
INFO:Iniciando calculo de diversidad lexicografica...
INFO:Iniciando calculo del promedio de la longuitud de los tweets...
INFO:Iniciando calculo del ratio de respuestas...
INFO:Iniciando calculo del promedio de los hashtags...
INFO:Iniciando calculo del promedio de menciones...
INFO:Iniciando calculo del promedio de palabras por tweet...
INFO:Iniciando calculo del promedio de diversidad de palabras...
INFO:Iniciando calculo del ratio de urls...
INFO:Registrando tablas...
INFO:Join entre tweets...
INFO:Calculo de features en tweetsRDD_ciborgs...
INFO:Calculando features para tweets...
INFO:Iniciando calculo de tweets por dia...
INFO:Iniciando calculo de tweets por hora...
INFO:Iniciando exploracion de las fuentes de los tweets...
INFO:Iniciando calculo de diversidad lexicografica...
INFO:Iniciando calculo del promedio de la longuitud de los tweets...
INFO:Iniciando calculo del ratio de respuestas...
INFO:Iniciando calculo del promedio de los hashtags...
INFO:Iniciando calculo del promedio de menciones...
INFO:Iniciando calculo del promedio de palabras por tweet...
INFO:Iniciando calculo del promedio de diversidad de palabras...
INFO:Iniciando calculo del ratio de urls...
INFO:Registrando tablas...
INFO:Join entre tweets...
INFO:Calculo de features en usuariosRDD_humanos...
INFO:Calculando features para usuarios...
INFO:Calculo de features en usuariosRDD_bots...
INFO:Calculando features para usuarios...
INFO:Calculo de features en usuariosRDD_ciborgs...
INFO:Calculando features para usuarios...
INFO:Realizando Union...
INFO:Realizando Join...
INFO:Guardando modelo...
INFO:Finalizando...
INFO:[13/Jun/2016:19:14:45] ENGINE Restarting because /home/jduarte/Workspace/TesisSpark/app.py changed.
INFO:[13/Jun/2016:19:14:45] ENGINE Stopped thread 'Autoreloader'.
INFO:[13/Jun/2016:19:14:45] ENGINE Bus STOPPING
INFO:[13/Jun/2016:19:14:46] ENGINE HTTP Server cherrypy._cpwsgi_server.CPWSGIServer(('0.0.0.0', 5432)) shut down
INFO:[13/Jun/2016:19:14:46] ENGINE Stopped thread '_TimeoutMonitor'.
INFO:[13/Jun/2016:19:14:46] ENGINE Bus STOPPED
INFO:[13/Jun/2016:19:14:46] ENGINE Bus EXITING
INFO:[13/Jun/2016:19:14:46] ENGINE Bus EXITED
INFO:[13/Jun/2016:19:14:46] ENGINE Waiting for child threads to terminate...
INFO:[13/Jun/2016:19:14:46] ENGINE Re-spawning /home/jduarte/Workspace/TesisSpark/server.py
INFO:Calentando motores...
INFO:Calentando motores...
INFO:[13/Jun/2016:19:17:27] ENGINE Bus STARTING
INFO:[13/Jun/2016:19:17:27] ENGINE Started monitor thread '_TimeoutMonitor'.
INFO:[13/Jun/2016:19:17:27] ENGINE Started monitor thread 'Autoreloader'.
INFO:[13/Jun/2016:19:17:27] ENGINE Serving on http://0.0.0.0:5432
INFO:[13/Jun/2016:19:17:27] ENGINE Bus STARTED
INFO:{u'humano': u'/home/jduarte/Workspace/datos/datos_cat/humano', u'ciborg': u'/home/jduarte/Workspace/datos/datos_cat/ciborg', u'bot': u'/home/jduarte/Workspace/datos/datos_cat/bot'}
INFO:Cargando timelines...
INFO:Calculo de features en tweetsRDD_humanos...
INFO:Calculando features para tweets...
INFO:Iniciando calculo de tweets por dia...
INFO:[13/Jun/2016:19:18:16] ENGINE Keyboard Interrupt: shutting down bus
INFO:[13/Jun/2016:19:18:16] ENGINE Bus STOPPING
ERROR:Exception on /entrenar_juez/ [POST]
Traceback (most recent call last):
  File "/usr/local/lib/python2.7/dist-packages/flask/app.py", line 1817, in wsgi_app
    response = self.full_dispatch_request()
  File "/usr/local/lib/python2.7/dist-packages/flask/app.py", line 1477, in full_dispatch_request
    rv = self.handle_user_exception(e)
  File "/usr/local/lib/python2.7/dist-packages/flask/app.py", line 1381, in handle_user_exception
    reraise(exc_type, exc_value, tb)
  File "/usr/local/lib/python2.7/dist-packages/flask/app.py", line 1475, in full_dispatch_request
    rv = self.dispatch_request()
  File "/usr/local/lib/python2.7/dist-packages/flask/app.py", line 1461, in dispatch_request
    return self.view_functions[rule.endpoint](**req.view_args)
  File "/home/jduarte/Workspace/TesisSpark/app.py", line 50, in entrenar_juez
    resultado = motor_clasificador.entrenar_juez(directorio)
  File "/home/jduarte/Workspace/TesisSpark/engine.py", line 67, in entrenar_juez
    tweets_features_humanos = tools.tweets_features(tweets_RDD_humanos, sqlcontext)
  File "/home/jduarte/Workspace/TesisSpark/tools.py", line 351, in tweets_features
    _tweets_x_dia = tweets_x_dia(tweets_RDD)
  File "/home/jduarte/Workspace/TesisSpark/tools.py", line 217, in tweets_x_dia
    porcentaje_dias).toDF().repartition("user_id")
  File "/home/jduarte/Herramientas/spark/python/lib/pyspark.zip/pyspark/sql/context.py", line 64, in toDF
    return sqlContext.createDataFrame(self, schema, sampleRatio)
  File "/home/jduarte/Herramientas/spark/python/lib/pyspark.zip/pyspark/sql/context.py", line 423, in createDataFrame
    rdd, schema = self._createFromRDD(data, schema, samplingRatio)
  File "/home/jduarte/Herramientas/spark/python/lib/pyspark.zip/pyspark/sql/context.py", line 310, in _createFromRDD
    struct = self._inferSchema(rdd, samplingRatio)
  File "/home/jduarte/Herramientas/spark/python/lib/pyspark.zip/pyspark/sql/context.py", line 254, in _inferSchema
    first = rdd.first()
  File "/home/jduarte/Herramientas/spark/python/lib/pyspark.zip/pyspark/rdd.py", line 1315, in first
    rs = self.take(1)
  File "/home/jduarte/Herramientas/spark/python/lib/pyspark.zip/pyspark/rdd.py", line 1297, in take
    res = self.context.runJob(self, takeUpToNumLeft, p)
  File "/home/jduarte/Herramientas/spark/python/lib/pyspark.zip/pyspark/context.py", line 939, in runJob
    port = self._jvm.PythonRDD.runJob(self._jsc.sc(), mappedRDD._jrdd, partitions)
  File "/home/jduarte/Herramientas/spark/python/lib/py4j-0.9-src.zip/py4j/java_gateway.py", line 813, in __call__
    answer, self.gateway_client, self.target_id, self.name)
  File "/home/jduarte/Herramientas/spark/python/lib/pyspark.zip/pyspark/sql/utils.py", line 45, in deco
    return f(*a, **kw)
  File "/home/jduarte/Herramientas/spark/python/lib/py4j-0.9-src.zip/py4j/protocol.py", line 308, in get_return_value
    format(target_id, ".", name), value)
Py4JJavaError: An error occurred while calling z:org.apache.spark.api.python.PythonRDD.runJob.
: org.apache.spark.SparkException: Job 3 cancelled as part of cancellation of all jobs
	at org.apache.spark.scheduler.DAGScheduler.org$apache$spark$scheduler$DAGScheduler$$failJobAndIndependentStages(DAGScheduler.scala:1431)
	at org.apache.spark.scheduler.DAGScheduler.handleJobCancellation(DAGScheduler.scala:1370)
	at org.apache.spark.scheduler.DAGScheduler$$anonfun$doCancelAllJobs$1.apply$mcVI$sp(DAGScheduler.scala:713)
	at org.apache.spark.scheduler.DAGScheduler$$anonfun$doCancelAllJobs$1.apply(DAGScheduler.scala:713)
	at org.apache.spark.scheduler.DAGScheduler$$anonfun$doCancelAllJobs$1.apply(DAGScheduler.scala:713)
	at scala.collection.mutable.HashSet.foreach(HashSet.scala:79)
	at org.apache.spark.scheduler.DAGScheduler.doCancelAllJobs(DAGScheduler.scala:713)
	at org.apache.spark.scheduler.DAGSchedulerEventProcessLoop.doOnReceive(DAGScheduler.scala:1622)
	at org.apache.spark.scheduler.DAGSchedulerEventProcessLoop.onReceive(DAGScheduler.scala:1599)
	at org.apache.spark.scheduler.DAGSchedulerEventProcessLoop.onReceive(DAGScheduler.scala:1588)
	at org.apache.spark.util.EventLoop$$anon$1.run(EventLoop.scala:48)
	at org.apache.spark.scheduler.DAGScheduler.runJob(DAGScheduler.scala:620)
	at org.apache.spark.SparkContext.runJob(SparkContext.scala:1832)
	at org.apache.spark.SparkContext.runJob(SparkContext.scala:1845)
	at org.apache.spark.SparkContext.runJob(SparkContext.scala:1858)
	at org.apache.spark.api.python.PythonRDD$.runJob(PythonRDD.scala:393)
	at org.apache.spark.api.python.PythonRDD.runJob(PythonRDD.scala)
	at sun.reflect.NativeMethodAccessorImpl.invoke0(Native Method)
	at sun.reflect.NativeMethodAccessorImpl.invoke(NativeMethodAccessorImpl.java:62)
	at sun.reflect.DelegatingMethodAccessorImpl.invoke(DelegatingMethodAccessorImpl.java:43)
	at java.lang.reflect.Method.invoke(Method.java:498)
	at py4j.reflection.MethodInvoker.invoke(MethodInvoker.java:231)
	at py4j.reflection.ReflectionEngine.invoke(ReflectionEngine.java:381)
	at py4j.Gateway.invoke(Gateway.java:259)
	at py4j.commands.AbstractCommand.invokeMethod(AbstractCommand.java:133)
	at py4j.commands.CallCommand.execute(CallCommand.java:79)
	at py4j.GatewayConnection.run(GatewayConnection.java:209)
	at java.lang.Thread.run(Thread.java:745)

INFO:[13/Jun/2016:19:18:17] ENGINE HTTP Server cherrypy._cpwsgi_server.CPWSGIServer(('0.0.0.0', 5432)) shut down
INFO:[13/Jun/2016:19:18:17] ENGINE Stopped thread 'Autoreloader'.
INFO:[13/Jun/2016:19:18:17] ENGINE Stopped thread '_TimeoutMonitor'.
INFO:[13/Jun/2016:19:18:17] ENGINE Bus STOPPED
INFO:[13/Jun/2016:19:18:17] ENGINE Bus EXITING
INFO:[13/Jun/2016:19:18:17] ENGINE Bus EXITED
INFO:[13/Jun/2016:19:18:17] ENGINE Waiting for child threads to terminate...
ERROR:Error while sending or receiving.
Traceback (most recent call last):
  File "/home/jduarte/Herramientas/spark/python/lib/py4j-0.9-src.zip/py4j/java_gateway.py", line 746, in send_command
    raise Py4JError("Answer from Java side is empty")
Py4JError: Answer from Java side is empty
INFO:Exception while sending command.
Traceback (most recent call last):
  File "/home/jduarte/Herramientas/spark/python/lib/py4j-0.9-src.zip/py4j/java_gateway.py", line 626, in send_command
    response = connection.send_command(command)
  File "/home/jduarte/Herramientas/spark/python/lib/py4j-0.9-src.zip/py4j/java_gateway.py", line 750, in send_command
    raise Py4JNetworkError("Error while sending or receiving", e)
Py4JNetworkError: Error while sending or receiving
ERROR:Error while sending or receiving.
Traceback (most recent call last):
  File "/home/jduarte/Herramientas/spark/python/lib/py4j-0.9-src.zip/py4j/java_gateway.py", line 746, in send_command
    raise Py4JError("Answer from Java side is empty")
Py4JError: Answer from Java side is empty
INFO:Exception while sending command.
Traceback (most recent call last):
  File "/home/jduarte/Herramientas/spark/python/lib/py4j-0.9-src.zip/py4j/java_gateway.py", line 626, in send_command
    response = connection.send_command(command)
  File "/home/jduarte/Herramientas/spark/python/lib/py4j-0.9-src.zip/py4j/java_gateway.py", line 750, in send_command
    raise Py4JNetworkError("Error while sending or receiving", e)
Py4JNetworkError: Error while sending or receiving
ERROR:An error occurred while trying to connect to the Java server
Traceback (most recent call last):
  File "/home/jduarte/Herramientas/spark/python/lib/py4j-0.9-src.zip/py4j/java_gateway.py", line 690, in start
    self.socket.connect((self.address, self.port))
  File "/usr/lib/python2.7/socket.py", line 224, in meth
    return getattr(self._sock,name)(*args)
error: [Errno 111] Connection refused
ERROR:An error occurred while trying to connect to the Java server
Traceback (most recent call last):
  File "/home/jduarte/Herramientas/spark/python/lib/py4j-0.9-src.zip/py4j/java_gateway.py", line 690, in start
    self.socket.connect((self.address, self.port))
  File "/usr/lib/python2.7/socket.py", line 224, in meth
    return getattr(self._sock,name)(*args)
error: [Errno 111] Connection refused
ERROR:An error occurred while trying to connect to the Java server
Traceback (most recent call last):
  File "/home/jduarte/Herramientas/spark/python/lib/py4j-0.9-src.zip/py4j/java_gateway.py", line 690, in start
    self.socket.connect((self.address, self.port))
  File "/usr/lib/python2.7/socket.py", line 224, in meth
    return getattr(self._sock,name)(*args)
error: [Errno 111] Connection refused
ERROR:An error occurred while trying to connect to the Java server
Traceback (most recent call last):
  File "/home/jduarte/Herramientas/spark/python/lib/py4j-0.9-src.zip/py4j/java_gateway.py", line 690, in start
    self.socket.connect((self.address, self.port))
  File "/usr/lib/python2.7/socket.py", line 224, in meth
    return getattr(self._sock,name)(*args)
error: [Errno 111] Connection refused
ERROR:An error occurred while trying to connect to the Java server
Traceback (most recent call last):
  File "/home/jduarte/Herramientas/spark/python/lib/py4j-0.9-src.zip/py4j/java_gateway.py", line 690, in start
    self.socket.connect((self.address, self.port))
  File "/usr/lib/python2.7/socket.py", line 224, in meth
    return getattr(self._sock,name)(*args)
error: [Errno 111] Connection refused
ERROR:An error occurred while trying to connect to the Java server
Traceback (most recent call last):
  File "/home/jduarte/Herramientas/spark/python/lib/py4j-0.9-src.zip/py4j/java_gateway.py", line 690, in start
    self.socket.connect((self.address, self.port))
  File "/usr/lib/python2.7/socket.py", line 224, in meth
    return getattr(self._sock,name)(*args)
error: [Errno 111] Connection refused
ERROR:An error occurred while trying to connect to the Java server
Traceback (most recent call last):
  File "/home/jduarte/Herramientas/spark/python/lib/py4j-0.9-src.zip/py4j/java_gateway.py", line 690, in start
    self.socket.connect((self.address, self.port))
  File "/usr/lib/python2.7/socket.py", line 224, in meth
    return getattr(self._sock,name)(*args)
error: [Errno 111] Connection refused
ERROR:An error occurred while trying to connect to the Java server
Traceback (most recent call last):
  File "/home/jduarte/Herramientas/spark/python/lib/py4j-0.9-src.zip/py4j/java_gateway.py", line 690, in start
    self.socket.connect((self.address, self.port))
  File "/usr/lib/python2.7/socket.py", line 224, in meth
    return getattr(self._sock,name)(*args)
error: [Errno 111] Connection refused
ERROR:An error occurred while trying to connect to the Java server
Traceback (most recent call last):
  File "/home/jduarte/Herramientas/spark/python/lib/py4j-0.9-src.zip/py4j/java_gateway.py", line 690, in start
    self.socket.connect((self.address, self.port))
  File "/usr/lib/python2.7/socket.py", line 224, in meth
    return getattr(self._sock,name)(*args)
error: [Errno 111] Connection refused
ERROR:An error occurred while trying to connect to the Java server
Traceback (most recent call last):
  File "/home/jduarte/Herramientas/spark/python/lib/py4j-0.9-src.zip/py4j/java_gateway.py", line 690, in start
    self.socket.connect((self.address, self.port))
  File "/usr/lib/python2.7/socket.py", line 224, in meth
    return getattr(self._sock,name)(*args)
error: [Errno 111] Connection refused
ERROR:An error occurred while trying to connect to the Java server
Traceback (most recent call last):
  File "/home/jduarte/Herramientas/spark/python/lib/py4j-0.9-src.zip/py4j/java_gateway.py", line 690, in start
    self.socket.connect((self.address, self.port))
  File "/usr/lib/python2.7/socket.py", line 224, in meth
    return getattr(self._sock,name)(*args)
error: [Errno 111] Connection refused
ERROR:An error occurred while trying to connect to the Java server
Traceback (most recent call last):
  File "/home/jduarte/Herramientas/spark/python/lib/py4j-0.9-src.zip/py4j/java_gateway.py", line 690, in start
    self.socket.connect((self.address, self.port))
  File "/usr/lib/python2.7/socket.py", line 224, in meth
    return getattr(self._sock,name)(*args)
error: [Errno 111] Connection refused
ERROR:An error occurred while trying to connect to the Java server
Traceback (most recent call last):
  File "/home/jduarte/Herramientas/spark/python/lib/py4j-0.9-src.zip/py4j/java_gateway.py", line 690, in start
    self.socket.connect((self.address, self.port))
  File "/usr/lib/python2.7/socket.py", line 224, in meth
    return getattr(self._sock,name)(*args)
error: [Errno 111] Connection refused
ERROR:An error occurred while trying to connect to the Java server
Traceback (most recent call last):
  File "/home/jduarte/Herramientas/spark/python/lib/py4j-0.9-src.zip/py4j/java_gateway.py", line 690, in start
    self.socket.connect((self.address, self.port))
  File "/usr/lib/python2.7/socket.py", line 224, in meth
    return getattr(self._sock,name)(*args)
error: [Errno 111] Connection refused
ERROR:An error occurred while trying to connect to the Java server
Traceback (most recent call last):
  File "/home/jduarte/Herramientas/spark/python/lib/py4j-0.9-src.zip/py4j/java_gateway.py", line 690, in start
    self.socket.connect((self.address, self.port))
  File "/usr/lib/python2.7/socket.py", line 224, in meth
    return getattr(self._sock,name)(*args)
error: [Errno 111] Connection refused
ERROR:An error occurred while trying to connect to the Java server
Traceback (most recent call last):
  File "/home/jduarte/Herramientas/spark/python/lib/py4j-0.9-src.zip/py4j/java_gateway.py", line 690, in start
    self.socket.connect((self.address, self.port))
  File "/usr/lib/python2.7/socket.py", line 224, in meth
    return getattr(self._sock,name)(*args)
error: [Errno 111] Connection refused
ERROR:An error occurred while trying to connect to the Java server
Traceback (most recent call last):
  File "/home/jduarte/Herramientas/spark/python/lib/py4j-0.9-src.zip/py4j/java_gateway.py", line 690, in start
    self.socket.connect((self.address, self.port))
  File "/usr/lib/python2.7/socket.py", line 224, in meth
    return getattr(self._sock,name)(*args)
error: [Errno 111] Connection refused
ERROR:An error occurred while trying to connect to the Java server
Traceback (most recent call last):
  File "/home/jduarte/Herramientas/spark/python/lib/py4j-0.9-src.zip/py4j/java_gateway.py", line 690, in start
    self.socket.connect((self.address, self.port))
  File "/usr/lib/python2.7/socket.py", line 224, in meth
    return getattr(self._sock,name)(*args)
error: [Errno 111] Connection refused
ERROR:An error occurred while trying to connect to the Java server
Traceback (most recent call last):
  File "/home/jduarte/Herramientas/spark/python/lib/py4j-0.9-src.zip/py4j/java_gateway.py", line 690, in start
    self.socket.connect((self.address, self.port))
  File "/usr/lib/python2.7/socket.py", line 224, in meth
    return getattr(self._sock,name)(*args)
error: [Errno 111] Connection refused
ERROR:An error occurred while trying to connect to the Java server
Traceback (most recent call last):
  File "/home/jduarte/Herramientas/spark/python/lib/py4j-0.9-src.zip/py4j/java_gateway.py", line 690, in start
    self.socket.connect((self.address, self.port))
  File "/usr/lib/python2.7/socket.py", line 224, in meth
    return getattr(self._sock,name)(*args)
error: [Errno 111] Connection refused
ERROR:An error occurred while trying to connect to the Java server
Traceback (most recent call last):
  File "/home/jduarte/Herramientas/spark/python/lib/py4j-0.9-src.zip/py4j/java_gateway.py", line 690, in start
    self.socket.connect((self.address, self.port))
  File "/usr/lib/python2.7/socket.py", line 224, in meth
    return getattr(self._sock,name)(*args)
error: [Errno 111] Connection refused
ERROR:An error occurred while trying to connect to the Java server
Traceback (most recent call last):
  File "/home/jduarte/Herramientas/spark/python/lib/py4j-0.9-src.zip/py4j/java_gateway.py", line 690, in start
    self.socket.connect((self.address, self.port))
  File "/usr/lib/python2.7/socket.py", line 224, in meth
    return getattr(self._sock,name)(*args)
error: [Errno 111] Connection refused
ERROR:An error occurred while trying to connect to the Java server
Traceback (most recent call last):
  File "/home/jduarte/Herramientas/spark/python/lib/py4j-0.9-src.zip/py4j/java_gateway.py", line 690, in start
    self.socket.connect((self.address, self.port))
  File "/usr/lib/python2.7/socket.py", line 224, in meth
    return getattr(self._sock,name)(*args)
error: [Errno 111] Connection refused
ERROR:An error occurred while trying to connect to the Java server
Traceback (most recent call last):
  File "/home/jduarte/Herramientas/spark/python/lib/py4j-0.9-src.zip/py4j/java_gateway.py", line 690, in start
    self.socket.connect((self.address, self.port))
  File "/usr/lib/python2.7/socket.py", line 224, in meth
    return getattr(self._sock,name)(*args)
error: [Errno 111] Connection refused
ERROR:An error occurred while trying to connect to the Java server
Traceback (most recent call last):
  File "/home/jduarte/Herramientas/spark/python/lib/py4j-0.9-src.zip/py4j/java_gateway.py", line 690, in start
    self.socket.connect((self.address, self.port))
  File "/usr/lib/python2.7/socket.py", line 224, in meth
    return getattr(self._sock,name)(*args)
error: [Errno 111] Connection refused
ERROR:An error occurred while trying to connect to the Java server
Traceback (most recent call last):
  File "/home/jduarte/Herramientas/spark/python/lib/py4j-0.9-src.zip/py4j/java_gateway.py", line 690, in start
    self.socket.connect((self.address, self.port))
  File "/usr/lib/python2.7/socket.py", line 224, in meth
    return getattr(self._sock,name)(*args)
error: [Errno 111] Connection refused
ERROR:An error occurred while trying to connect to the Java server
Traceback (most recent call last):
  File "/home/jduarte/Herramientas/spark/python/lib/py4j-0.9-src.zip/py4j/java_gateway.py", line 690, in start
    self.socket.connect((self.address, self.port))
  File "/usr/lib/python2.7/socket.py", line 224, in meth
    return getattr(self._sock,name)(*args)
error: [Errno 111] Connection refused
ERROR:An error occurred while trying to connect to the Java server
Traceback (most recent call last):
  File "/home/jduarte/Herramientas/spark/python/lib/py4j-0.9-src.zip/py4j/java_gateway.py", line 690, in start
    self.socket.connect((self.address, self.port))
  File "/usr/lib/python2.7/socket.py", line 224, in meth
    return getattr(self._sock,name)(*args)
error: [Errno 111] Connection refused
ERROR:An error occurred while trying to connect to the Java server
Traceback (most recent call last):
  File "/home/jduarte/Herramientas/spark/python/lib/py4j-0.9-src.zip/py4j/java_gateway.py", line 690, in start
    self.socket.connect((self.address, self.port))
  File "/usr/lib/python2.7/socket.py", line 224, in meth
    return getattr(self._sock,name)(*args)
error: [Errno 111] Connection refused
ERROR:An error occurred while trying to connect to the Java server
Traceback (most recent call last):
  File "/home/jduarte/Herramientas/spark/python/lib/py4j-0.9-src.zip/py4j/java_gateway.py", line 690, in start
    self.socket.connect((self.address, self.port))
  File "/usr/lib/python2.7/socket.py", line 224, in meth
    return getattr(self._sock,name)(*args)
error: [Errno 111] Connection refused
ERROR:An error occurred while trying to connect to the Java server
Traceback (most recent call last):
  File "/home/jduarte/Herramientas/spark/python/lib/py4j-0.9-src.zip/py4j/java_gateway.py", line 690, in start
    self.socket.connect((self.address, self.port))
  File "/usr/lib/python2.7/socket.py", line 224, in meth
    return getattr(self._sock,name)(*args)
error: [Errno 111] Connection refused
ERROR:An error occurred while trying to connect to the Java server
Traceback (most recent call last):
  File "/home/jduarte/Herramientas/spark/python/lib/py4j-0.9-src.zip/py4j/java_gateway.py", line 690, in start
    self.socket.connect((self.address, self.port))
  File "/usr/lib/python2.7/socket.py", line 224, in meth
    return getattr(self._sock,name)(*args)
error: [Errno 111] Connection refused
ERROR:An error occurred while trying to connect to the Java server
Traceback (most recent call last):
  File "/home/jduarte/Herramientas/spark/python/lib/py4j-0.9-src.zip/py4j/java_gateway.py", line 690, in start
    self.socket.connect((self.address, self.port))
  File "/usr/lib/python2.7/socket.py", line 224, in meth
    return getattr(self._sock,name)(*args)
error: [Errno 111] Connection refused
ERROR:An error occurred while trying to connect to the Java server
Traceback (most recent call last):
  File "/home/jduarte/Herramientas/spark/python/lib/py4j-0.9-src.zip/py4j/java_gateway.py", line 690, in start
    self.socket.connect((self.address, self.port))
  File "/usr/lib/python2.7/socket.py", line 224, in meth
    return getattr(self._sock,name)(*args)
error: [Errno 111] Connection refused
ERROR:An error occurred while trying to connect to the Java server
Traceback (most recent call last):
  File "/home/jduarte/Herramientas/spark/python/lib/py4j-0.9-src.zip/py4j/java_gateway.py", line 690, in start
    self.socket.connect((self.address, self.port))
  File "/usr/lib/python2.7/socket.py", line 224, in meth
    return getattr(self._sock,name)(*args)
error: [Errno 111] Connection refused
ERROR:An error occurred while trying to connect to the Java server
Traceback (most recent call last):
  File "/home/jduarte/Herramientas/spark/python/lib/py4j-0.9-src.zip/py4j/java_gateway.py", line 690, in start
    self.socket.connect((self.address, self.port))
  File "/usr/lib/python2.7/socket.py", line 224, in meth
    return getattr(self._sock,name)(*args)
error: [Errno 111] Connection refused
ERROR:An error occurred while trying to connect to the Java server
Traceback (most recent call last):
  File "/home/jduarte/Herramientas/spark/python/lib/py4j-0.9-src.zip/py4j/java_gateway.py", line 690, in start
    self.socket.connect((self.address, self.port))
  File "/usr/lib/python2.7/socket.py", line 224, in meth
    return getattr(self._sock,name)(*args)
error: [Errno 111] Connection refused
ERROR:An error occurred while trying to connect to the Java server
Traceback (most recent call last):
  File "/home/jduarte/Herramientas/spark/python/lib/py4j-0.9-src.zip/py4j/java_gateway.py", line 690, in start
    self.socket.connect((self.address, self.port))
  File "/usr/lib/python2.7/socket.py", line 224, in meth
    return getattr(self._sock,name)(*args)
error: [Errno 111] Connection refused
ERROR:An error occurred while trying to connect to the Java server
Traceback (most recent call last):
  File "/home/jduarte/Herramientas/spark/python/lib/py4j-0.9-src.zip/py4j/java_gateway.py", line 690, in start
    self.socket.connect((self.address, self.port))
  File "/usr/lib/python2.7/socket.py", line 224, in meth
    return getattr(self._sock,name)(*args)
error: [Errno 111] Connection refused
ERROR:An error occurred while trying to connect to the Java server
Traceback (most recent call last):
  File "/home/jduarte/Herramientas/spark/python/lib/py4j-0.9-src.zip/py4j/java_gateway.py", line 690, in start
    self.socket.connect((self.address, self.port))
  File "/usr/lib/python2.7/socket.py", line 224, in meth
    return getattr(self._sock,name)(*args)
error: [Errno 111] Connection refused
ERROR:An error occurred while trying to connect to the Java server
Traceback (most recent call last):
  File "/home/jduarte/Herramientas/spark/python/lib/py4j-0.9-src.zip/py4j/java_gateway.py", line 690, in start
    self.socket.connect((self.address, self.port))
  File "/usr/lib/python2.7/socket.py", line 224, in meth
    return getattr(self._sock,name)(*args)
error: [Errno 111] Connection refused
ERROR:An error occurred while trying to connect to the Java server
Traceback (most recent call last):
  File "/home/jduarte/Herramientas/spark/python/lib/py4j-0.9-src.zip/py4j/java_gateway.py", line 690, in start
    self.socket.connect((self.address, self.port))
  File "/usr/lib/python2.7/socket.py", line 224, in meth
    return getattr(self._sock,name)(*args)
error: [Errno 111] Connection refused
ERROR:An error occurred while trying to connect to the Java server
Traceback (most recent call last):
  File "/home/jduarte/Herramientas/spark/python/lib/py4j-0.9-src.zip/py4j/java_gateway.py", line 690, in start
    self.socket.connect((self.address, self.port))
  File "/usr/lib/python2.7/socket.py", line 224, in meth
    return getattr(self._sock,name)(*args)
error: [Errno 111] Connection refused
ERROR:An error occurred while trying to connect to the Java server
Traceback (most recent call last):
  File "/home/jduarte/Herramientas/spark/python/lib/py4j-0.9-src.zip/py4j/java_gateway.py", line 690, in start
    self.socket.connect((self.address, self.port))
  File "/usr/lib/python2.7/socket.py", line 224, in meth
    return getattr(self._sock,name)(*args)
error: [Errno 111] Connection refused
ERROR:An error occurred while trying to connect to the Java server
Traceback (most recent call last):
  File "/home/jduarte/Herramientas/spark/python/lib/py4j-0.9-src.zip/py4j/java_gateway.py", line 690, in start
    self.socket.connect((self.address, self.port))
  File "/usr/lib/python2.7/socket.py", line 224, in meth
    return getattr(self._sock,name)(*args)
error: [Errno 111] Connection refused
ERROR:An error occurred while trying to connect to the Java server
Traceback (most recent call last):
  File "/home/jduarte/Herramientas/spark/python/lib/py4j-0.9-src.zip/py4j/java_gateway.py", line 690, in start
    self.socket.connect((self.address, self.port))
  File "/usr/lib/python2.7/socket.py", line 224, in meth
    return getattr(self._sock,name)(*args)
error: [Errno 111] Connection refused
ERROR:An error occurred while trying to connect to the Java server
Traceback (most recent call last):
  File "/home/jduarte/Herramientas/spark/python/lib/py4j-0.9-src.zip/py4j/java_gateway.py", line 690, in start
    self.socket.connect((self.address, self.port))
  File "/usr/lib/python2.7/socket.py", line 224, in meth
    return getattr(self._sock,name)(*args)
error: [Errno 111] Connection refused
ERROR:An error occurred while trying to connect to the Java server
Traceback (most recent call last):
  File "/home/jduarte/Herramientas/spark/python/lib/py4j-0.9-src.zip/py4j/java_gateway.py", line 690, in start
    self.socket.connect((self.address, self.port))
  File "/usr/lib/python2.7/socket.py", line 224, in meth
    return getattr(self._sock,name)(*args)
error: [Errno 111] Connection refused
ERROR:An error occurred while trying to connect to the Java server
Traceback (most recent call last):
  File "/home/jduarte/Herramientas/spark/python/lib/py4j-0.9-src.zip/py4j/java_gateway.py", line 690, in start
    self.socket.connect((self.address, self.port))
  File "/usr/lib/python2.7/socket.py", line 224, in meth
    return getattr(self._sock,name)(*args)
error: [Errno 111] Connection refused
ERROR:An error occurred while trying to connect to the Java server
Traceback (most recent call last):
  File "/home/jduarte/Herramientas/spark/python/lib/py4j-0.9-src.zip/py4j/java_gateway.py", line 690, in start
    self.socket.connect((self.address, self.port))
  File "/usr/lib/python2.7/socket.py", line 224, in meth
    return getattr(self._sock,name)(*args)
error: [Errno 111] Connection refused
ERROR:An error occurred while trying to connect to the Java server
Traceback (most recent call last):
  File "/home/jduarte/Herramientas/spark/python/lib/py4j-0.9-src.zip/py4j/java_gateway.py", line 690, in start
    self.socket.connect((self.address, self.port))
  File "/usr/lib/python2.7/socket.py", line 224, in meth
    return getattr(self._sock,name)(*args)
error: [Errno 111] Connection refused
ERROR:An error occurred while trying to connect to the Java server
Traceback (most recent call last):
  File "/home/jduarte/Herramientas/spark/python/lib/py4j-0.9-src.zip/py4j/java_gateway.py", line 690, in start
    self.socket.connect((self.address, self.port))
  File "/usr/lib/python2.7/socket.py", line 224, in meth
    return getattr(self._sock,name)(*args)
error: [Errno 111] Connection refused
ERROR:An error occurred while trying to connect to the Java server
Traceback (most recent call last):
  File "/home/jduarte/Herramientas/spark/python/lib/py4j-0.9-src.zip/py4j/java_gateway.py", line 690, in start
    self.socket.connect((self.address, self.port))
  File "/usr/lib/python2.7/socket.py", line 224, in meth
    return getattr(self._sock,name)(*args)
error: [Errno 111] Connection refused
ERROR:An error occurred while trying to connect to the Java server
Traceback (most recent call last):
  File "/home/jduarte/Herramientas/spark/python/lib/py4j-0.9-src.zip/py4j/java_gateway.py", line 690, in start
    self.socket.connect((self.address, self.port))
  File "/usr/lib/python2.7/socket.py", line 224, in meth
    return getattr(self._sock,name)(*args)
error: [Errno 111] Connection refused
ERROR:An error occurred while trying to connect to the Java server
Traceback (most recent call last):
  File "/home/jduarte/Herramientas/spark/python/lib/py4j-0.9-src.zip/py4j/java_gateway.py", line 690, in start
    self.socket.connect((self.address, self.port))
  File "/usr/lib/python2.7/socket.py", line 224, in meth
    return getattr(self._sock,name)(*args)
error: [Errno 111] Connection refused
ERROR:An error occurred while trying to connect to the Java server
Traceback (most recent call last):
  File "/home/jduarte/Herramientas/spark/python/lib/py4j-0.9-src.zip/py4j/java_gateway.py", line 690, in start
    self.socket.connect((self.address, self.port))
  File "/usr/lib/python2.7/socket.py", line 224, in meth
    return getattr(self._sock,name)(*args)
error: [Errno 111] Connection refused
ERROR:An error occurred while trying to connect to the Java server
Traceback (most recent call last):
  File "/home/jduarte/Herramientas/spark/python/lib/py4j-0.9-src.zip/py4j/java_gateway.py", line 690, in start
    self.socket.connect((self.address, self.port))
  File "/usr/lib/python2.7/socket.py", line 224, in meth
    return getattr(self._sock,name)(*args)
error: [Errno 111] Connection refused
ERROR:An error occurred while trying to connect to the Java server
Traceback (most recent call last):
  File "/home/jduarte/Herramientas/spark/python/lib/py4j-0.9-src.zip/py4j/java_gateway.py", line 690, in start
    self.socket.connect((self.address, self.port))
  File "/usr/lib/python2.7/socket.py", line 224, in meth
    return getattr(self._sock,name)(*args)
error: [Errno 111] Connection refused
ERROR:An error occurred while trying to connect to the Java server
Traceback (most recent call last):
  File "/home/jduarte/Herramientas/spark/python/lib/py4j-0.9-src.zip/py4j/java_gateway.py", line 690, in start
    self.socket.connect((self.address, self.port))
  File "/usr/lib/python2.7/socket.py", line 224, in meth
    return getattr(self._sock,name)(*args)
error: [Errno 111] Connection refused
ERROR:An error occurred while trying to connect to the Java server
Traceback (most recent call last):
  File "/home/jduarte/Herramientas/spark/python/lib/py4j-0.9-src.zip/py4j/java_gateway.py", line 690, in start
    self.socket.connect((self.address, self.port))
  File "/usr/lib/python2.7/socket.py", line 224, in meth
    return getattr(self._sock,name)(*args)
error: [Errno 111] Connection refused
ERROR:An error occurred while trying to connect to the Java server
Traceback (most recent call last):
  File "/home/jduarte/Herramientas/spark/python/lib/py4j-0.9-src.zip/py4j/java_gateway.py", line 690, in start
    self.socket.connect((self.address, self.port))
  File "/usr/lib/python2.7/socket.py", line 224, in meth
    return getattr(self._sock,name)(*args)
error: [Errno 111] Connection refused
ERROR:An error occurred while trying to connect to the Java server
Traceback (most recent call last):
  File "/home/jduarte/Herramientas/spark/python/lib/py4j-0.9-src.zip/py4j/java_gateway.py", line 690, in start
    self.socket.connect((self.address, self.port))
  File "/usr/lib/python2.7/socket.py", line 224, in meth
    return getattr(self._sock,name)(*args)
error: [Errno 111] Connection refused
ERROR:An error occurred while trying to connect to the Java server
Traceback (most recent call last):
  File "/home/jduarte/Herramientas/spark/python/lib/py4j-0.9-src.zip/py4j/java_gateway.py", line 690, in start
    self.socket.connect((self.address, self.port))
  File "/usr/lib/python2.7/socket.py", line 224, in meth
    return getattr(self._sock,name)(*args)
error: [Errno 111] Connection refused
ERROR:An error occurred while trying to connect to the Java server
Traceback (most recent call last):
  File "/home/jduarte/Herramientas/spark/python/lib/py4j-0.9-src.zip/py4j/java_gateway.py", line 690, in start
    self.socket.connect((self.address, self.port))
  File "/usr/lib/python2.7/socket.py", line 224, in meth
    return getattr(self._sock,name)(*args)
error: [Errno 111] Connection refused
ERROR:An error occurred while trying to connect to the Java server
Traceback (most recent call last):
  File "/home/jduarte/Herramientas/spark/python/lib/py4j-0.9-src.zip/py4j/java_gateway.py", line 690, in start
    self.socket.connect((self.address, self.port))
  File "/usr/lib/python2.7/socket.py", line 224, in meth
    return getattr(self._sock,name)(*args)
error: [Errno 111] Connection refused
ERROR:An error occurred while trying to connect to the Java server
Traceback (most recent call last):
  File "/home/jduarte/Herramientas/spark/python/lib/py4j-0.9-src.zip/py4j/java_gateway.py", line 690, in start
    self.socket.connect((self.address, self.port))
  File "/usr/lib/python2.7/socket.py", line 224, in meth
    return getattr(self._sock,name)(*args)
error: [Errno 111] Connection refused
ERROR:An error occurred while trying to connect to the Java server
Traceback (most recent call last):
  File "/home/jduarte/Herramientas/spark/python/lib/py4j-0.9-src.zip/py4j/java_gateway.py", line 690, in start
    self.socket.connect((self.address, self.port))
  File "/usr/lib/python2.7/socket.py", line 224, in meth
    return getattr(self._sock,name)(*args)
error: [Errno 111] Connection refused
ERROR:An error occurred while trying to connect to the Java server
Traceback (most recent call last):
  File "/home/jduarte/Herramientas/spark/python/lib/py4j-0.9-src.zip/py4j/java_gateway.py", line 690, in start
    self.socket.connect((self.address, self.port))
  File "/usr/lib/python2.7/socket.py", line 224, in meth
    return getattr(self._sock,name)(*args)
error: [Errno 111] Connection refused
ERROR:An error occurred while trying to connect to the Java server
Traceback (most recent call last):
  File "/home/jduarte/Herramientas/spark/python/lib/py4j-0.9-src.zip/py4j/java_gateway.py", line 690, in start
    self.socket.connect((self.address, self.port))
  File "/usr/lib/python2.7/socket.py", line 224, in meth
    return getattr(self._sock,name)(*args)
error: [Errno 111] Connection refused
INFO:Calentando motores...
INFO:[13/Jun/2016:19:18:28] ENGINE Bus STARTING
INFO:[13/Jun/2016:19:18:28] ENGINE Started monitor thread '_TimeoutMonitor'.
INFO:[13/Jun/2016:19:18:28] ENGINE Started monitor thread 'Autoreloader'.
INFO:[13/Jun/2016:19:18:28] ENGINE Serving on http://0.0.0.0:5432
INFO:[13/Jun/2016:19:18:28] ENGINE Bus STARTED
INFO:{u'humano': u'/home/jduarte/Workspace/datos/datos_cat/humano', u'ciborg': u'/home/jduarte/Workspace/datos/datos_cat/ciborg', u'bot': u'/home/jduarte/Workspace/datos/datos_cat/bot'}
INFO:Cargando timelines...
INFO:Calculo de features en tweetsRDD_humanos...
INFO:Calculando features para tweets...
INFO:Iniciando calculo de tweets por dia...
INFO:Iniciando calculo de tweets por hora...
INFO:Iniciando exploracion de las fuentes de los tweets...
INFO:Iniciando calculo de diversidad lexicografica...
INFO:Iniciando calculo del promedio de la longuitud de los tweets...
INFO:Iniciando calculo del ratio de respuestas...
INFO:Iniciando calculo del promedio de los hashtags...
INFO:Iniciando calculo del promedio de menciones...
INFO:Iniciando calculo del promedio de palabras por tweet...
INFO:Iniciando calculo del promedio de diversidad de palabras...
INFO:Iniciando calculo del ratio de urls...
INFO:Registrando tablas...
INFO:Join entre tweets...
INFO:Calculo de features en tweetsRDD_bots...
INFO:Calculando features para tweets...
INFO:Iniciando calculo de tweets por dia...
INFO:Iniciando calculo de tweets por hora...
INFO:Iniciando exploracion de las fuentes de los tweets...
INFO:Iniciando calculo de diversidad lexicografica...
INFO:Iniciando calculo del promedio de la longuitud de los tweets...
INFO:Iniciando calculo del ratio de respuestas...
INFO:Iniciando calculo del promedio de los hashtags...
INFO:Iniciando calculo del promedio de menciones...
INFO:Iniciando calculo del promedio de palabras por tweet...
INFO:Iniciando calculo del promedio de diversidad de palabras...
INFO:Iniciando calculo del ratio de urls...
INFO:Registrando tablas...
INFO:Join entre tweets...
INFO:Calculo de features en tweetsRDD_ciborgs...
INFO:Calculando features para tweets...
INFO:Iniciando calculo de tweets por dia...
INFO:Iniciando calculo de tweets por hora...
INFO:Iniciando exploracion de las fuentes de los tweets...
INFO:Iniciando calculo de diversidad lexicografica...
INFO:Iniciando calculo del promedio de la longuitud de los tweets...
INFO:Iniciando calculo del ratio de respuestas...
INFO:Iniciando calculo del promedio de los hashtags...
INFO:Iniciando calculo del promedio de menciones...
INFO:Iniciando calculo del promedio de palabras por tweet...
INFO:Iniciando calculo del promedio de diversidad de palabras...
INFO:Iniciando calculo del ratio de urls...
INFO:Registrando tablas...
INFO:Join entre tweets...
INFO:Calculo de features en usuariosRDD_humanos...
INFO:Calculando features para usuarios...
INFO:Calculo de features en usuariosRDD_bots...
INFO:Calculando features para usuarios...
INFO:Calculo de features en usuariosRDD_ciborgs...
INFO:Calculando features para usuarios...
INFO:Realizando Union...
INFO:Realizando Join...
INFO:Guardando modelo...
INFO:Finalizando...
INFO:Cargando arhcivos...
ERROR:Exception on /evaluar/ [POST]
Traceback (most recent call last):
  File "/usr/local/lib/python2.7/dist-packages/flask/app.py", line 1817, in wsgi_app
    response = self.full_dispatch_request()
  File "/usr/local/lib/python2.7/dist-packages/flask/app.py", line 1477, in full_dispatch_request
    rv = self.handle_user_exception(e)
  File "/usr/local/lib/python2.7/dist-packages/flask/app.py", line 1381, in handle_user_exception
    reraise(exc_type, exc_value, tb)
  File "/usr/local/lib/python2.7/dist-packages/flask/app.py", line 1475, in full_dispatch_request
    rv = self.dispatch_request()
  File "/usr/local/lib/python2.7/dist-packages/flask/app.py", line 1461, in dispatch_request
    return self.view_functions[rule.endpoint](**req.view_args)
  File "/home/jduarte/Workspace/TesisSpark/app.py", line 26, in evaluar
    resultado = motor_clasificador.evaluar(directorio)
  File "/home/jduarte/Workspace/TesisSpark/engine.py", line 178, in evaluar
    features = tools.timeline_features(sc, dir_timeline)
  File "/home/jduarte/Workspace/TesisSpark/tools.py", line 441, in timeline_features
    df = sqlcontext.jsonRDD(timeline)
  File "/home/jduarte/Herramientas/spark/python/lib/pyspark.zip/pyspark/sql/context.py", line 524, in jsonRDD
    df = self._ssql_ctx.jsonRDD(jrdd.rdd(), samplingRatio)
  File "/home/jduarte/Herramientas/spark/python/lib/py4j-0.9-src.zip/py4j/java_gateway.py", line 813, in __call__
    answer, self.gateway_client, self.target_id, self.name)
  File "/home/jduarte/Herramientas/spark/python/lib/pyspark.zip/pyspark/sql/utils.py", line 45, in deco
    return f(*a, **kw)
  File "/home/jduarte/Herramientas/spark/python/lib/py4j-0.9-src.zip/py4j/protocol.py", line 308, in get_return_value
    format(target_id, ".", name), value)
Py4JJavaError: An error occurred while calling o1680.jsonRDD.
: org.apache.hadoop.mapred.InvalidInputException: Input path does not exist: file:/home/jduarte/Workspace/datos/174312811
	at org.apache.hadoop.mapred.FileInputFormat.listStatus(FileInputFormat.java:251)
	at org.apache.hadoop.mapred.FileInputFormat.getSplits(FileInputFormat.java:270)
	at org.apache.spark.rdd.HadoopRDD.getPartitions(HadoopRDD.scala:199)
	at org.apache.spark.rdd.RDD$$anonfun$partitions$2.apply(RDD.scala:239)
	at org.apache.spark.rdd.RDD$$anonfun$partitions$2.apply(RDD.scala:237)
	at scala.Option.getOrElse(Option.scala:120)
	at org.apache.spark.rdd.RDD.partitions(RDD.scala:237)
	at org.apache.spark.rdd.MapPartitionsRDD.getPartitions(MapPartitionsRDD.scala:35)
	at org.apache.spark.rdd.RDD$$anonfun$partitions$2.apply(RDD.scala:239)
	at org.apache.spark.rdd.RDD$$anonfun$partitions$2.apply(RDD.scala:237)
	at scala.Option.getOrElse(Option.scala:120)
	at org.apache.spark.rdd.RDD.partitions(RDD.scala:237)
	at org.apache.spark.api.python.PythonRDD.getPartitions(PythonRDD.scala:58)
	at org.apache.spark.rdd.RDD$$anonfun$partitions$2.apply(RDD.scala:239)
	at org.apache.spark.rdd.RDD$$anonfun$partitions$2.apply(RDD.scala:237)
	at scala.Option.getOrElse(Option.scala:120)
	at org.apache.spark.rdd.RDD.partitions(RDD.scala:237)
	at org.apache.spark.rdd.MapPartitionsRDD.getPartitions(MapPartitionsRDD.scala:35)
	at org.apache.spark.rdd.RDD$$anonfun$partitions$2.apply(RDD.scala:239)
	at org.apache.spark.rdd.RDD$$anonfun$partitions$2.apply(RDD.scala:237)
	at scala.Option.getOrElse(Option.scala:120)
	at org.apache.spark.rdd.RDD.partitions(RDD.scala:237)
	at org.apache.spark.rdd.MapPartitionsRDD.getPartitions(MapPartitionsRDD.scala:35)
	at org.apache.spark.rdd.RDD$$anonfun$partitions$2.apply(RDD.scala:239)
	at org.apache.spark.rdd.RDD$$anonfun$partitions$2.apply(RDD.scala:237)
	at scala.Option.getOrElse(Option.scala:120)
	at org.apache.spark.rdd.RDD.partitions(RDD.scala:237)
	at org.apache.spark.rdd.RDD$$anonfun$treeAggregate$1.apply(RDD.scala:1129)
	at org.apache.spark.rdd.RDDOperationScope$.withScope(RDDOperationScope.scala:150)
	at org.apache.spark.rdd.RDDOperationScope$.withScope(RDDOperationScope.scala:111)
	at org.apache.spark.rdd.RDD.withScope(RDD.scala:316)
	at org.apache.spark.rdd.RDD.treeAggregate(RDD.scala:1127)
	at org.apache.spark.sql.execution.datasources.json.InferSchema$.infer(InferSchema.scala:65)
	at org.apache.spark.sql.execution.datasources.json.JSONRelation$$anonfun$4.apply(JSONRelation.scala:114)
	at org.apache.spark.sql.execution.datasources.json.JSONRelation$$anonfun$4.apply(JSONRelation.scala:109)
	at scala.Option.getOrElse(Option.scala:120)
	at org.apache.spark.sql.execution.datasources.json.JSONRelation.dataSchema$lzycompute(JSONRelation.scala:109)
	at org.apache.spark.sql.execution.datasources.json.JSONRelation.dataSchema(JSONRelation.scala:108)
	at org.apache.spark.sql.sources.HadoopFsRelation.schema$lzycompute(interfaces.scala:636)
	at org.apache.spark.sql.sources.HadoopFsRelation.schema(interfaces.scala:635)
	at org.apache.spark.sql.execution.datasources.LogicalRelation.<init>(LogicalRelation.scala:37)
	at org.apache.spark.sql.SQLContext.baseRelationToDataFrame(SQLContext.scala:442)
	at org.apache.spark.sql.DataFrameReader.json(DataFrameReader.scala:288)
	at org.apache.spark.sql.SQLContext.jsonRDD(SQLContext.scala:1090)
	at sun.reflect.NativeMethodAccessorImpl.invoke0(Native Method)
	at sun.reflect.NativeMethodAccessorImpl.invoke(NativeMethodAccessorImpl.java:62)
	at sun.reflect.DelegatingMethodAccessorImpl.invoke(DelegatingMethodAccessorImpl.java:43)
	at java.lang.reflect.Method.invoke(Method.java:498)
	at py4j.reflection.MethodInvoker.invoke(MethodInvoker.java:231)
	at py4j.reflection.ReflectionEngine.invoke(ReflectionEngine.java:381)
	at py4j.Gateway.invoke(Gateway.java:259)
	at py4j.commands.AbstractCommand.invokeMethod(AbstractCommand.java:133)
	at py4j.commands.CallCommand.execute(CallCommand.java:79)
	at py4j.GatewayConnection.run(GatewayConnection.java:209)
	at java.lang.Thread.run(Thread.java:745)

INFO:Cargando arhcivos...
INFO:Calculando features para tweets...
INFO:Iniciando calculo de tweets por dia...
INFO:Iniciando calculo de tweets por hora...
INFO:Iniciando exploracion de las fuentes de los tweets...
INFO:Iniciando calculo de diversidad lexicografica...
INFO:Iniciando calculo del promedio de la longuitud de los tweets...
INFO:Iniciando calculo del ratio de respuestas...
INFO:Iniciando calculo del promedio de los hashtags...
INFO:Iniciando calculo del promedio de menciones...
INFO:Iniciando calculo del promedio de palabras por tweet...
INFO:Iniciando calculo del promedio de diversidad de palabras...
INFO:Iniciando calculo del ratio de urls...
INFO:Registrando tablas...
INFO:Join entre tweets...
INFO:Calculando features para usuarios...
INFO:Realizando join de usuarios con tweets...
INFO:Finalizado el join...
ERROR:Exception on /evaluar/ [POST]
Traceback (most recent call last):
  File "/usr/local/lib/python2.7/dist-packages/flask/app.py", line 1817, in wsgi_app
    response = self.full_dispatch_request()
  File "/usr/local/lib/python2.7/dist-packages/flask/app.py", line 1477, in full_dispatch_request
    rv = self.handle_user_exception(e)
  File "/usr/local/lib/python2.7/dist-packages/flask/app.py", line 1381, in handle_user_exception
    reraise(exc_type, exc_value, tb)
  File "/usr/local/lib/python2.7/dist-packages/flask/app.py", line 1475, in full_dispatch_request
    rv = self.dispatch_request()
  File "/usr/local/lib/python2.7/dist-packages/flask/app.py", line 1461, in dispatch_request
    return self.view_functions[rule.endpoint](**req.view_args)
  File "/home/jduarte/Workspace/TesisSpark/app.py", line 27, in evaluar
    return json.dumps(dict(resultado=resultado))
  File "/usr/lib/python2.7/json/__init__.py", line 243, in dumps
    return _default_encoder.encode(obj)
  File "/usr/lib/python2.7/json/encoder.py", line 207, in encode
    chunks = self.iterencode(o, _one_shot=True)
  File "/usr/lib/python2.7/json/encoder.py", line 270, in iterencode
    return _iterencode(o, 0)
  File "/usr/lib/python2.7/json/encoder.py", line 184, in default
    raise TypeError(repr(o) + " is not JSON serializable")
TypeError: MapPartitionsRDD[926] at mapPartitions at PythonMLLibAPI.scala:1493 is not JSON serializable
INFO:[13/Jun/2016:19:26:01] ENGINE Keyboard Interrupt: shutting down bus
INFO:[13/Jun/2016:19:26:01] ENGINE Bus STOPPING
INFO:[13/Jun/2016:19:26:01] ENGINE HTTP Server cherrypy._cpwsgi_server.CPWSGIServer(('0.0.0.0', 5432)) shut down
INFO:[13/Jun/2016:19:26:01] ENGINE Stopped thread 'Autoreloader'.
INFO:[13/Jun/2016:19:26:01] ENGINE Stopped thread '_TimeoutMonitor'.
INFO:[13/Jun/2016:19:26:01] ENGINE Bus STOPPED
INFO:[13/Jun/2016:19:26:01] ENGINE Bus EXITING
INFO:[13/Jun/2016:19:26:01] ENGINE Bus EXITED
INFO:[13/Jun/2016:19:26:01] ENGINE Waiting for child threads to terminate...
ERROR:Error while sending or receiving.
Traceback (most recent call last):
  File "/home/jduarte/Herramientas/spark/python/lib/py4j-0.9-src.zip/py4j/java_gateway.py", line 746, in send_command
    raise Py4JError("Answer from Java side is empty")
Py4JError: Answer from Java side is empty
INFO:Exception while sending command.
Traceback (most recent call last):
  File "/home/jduarte/Herramientas/spark/python/lib/py4j-0.9-src.zip/py4j/java_gateway.py", line 626, in send_command
    response = connection.send_command(command)
  File "/home/jduarte/Herramientas/spark/python/lib/py4j-0.9-src.zip/py4j/java_gateway.py", line 750, in send_command
    raise Py4JNetworkError("Error while sending or receiving", e)
Py4JNetworkError: Error while sending or receiving
ERROR:Error while sending or receiving.
Traceback (most recent call last):
  File "/home/jduarte/Herramientas/spark/python/lib/py4j-0.9-src.zip/py4j/java_gateway.py", line 746, in send_command
    raise Py4JError("Answer from Java side is empty")
Py4JError: Answer from Java side is empty
INFO:Exception while sending command.
Traceback (most recent call last):
  File "/home/jduarte/Herramientas/spark/python/lib/py4j-0.9-src.zip/py4j/java_gateway.py", line 626, in send_command
    response = connection.send_command(command)
  File "/home/jduarte/Herramientas/spark/python/lib/py4j-0.9-src.zip/py4j/java_gateway.py", line 750, in send_command
    raise Py4JNetworkError("Error while sending or receiving", e)
Py4JNetworkError: Error while sending or receiving
ERROR:An error occurred while trying to connect to the Java server
Traceback (most recent call last):
  File "/home/jduarte/Herramientas/spark/python/lib/py4j-0.9-src.zip/py4j/java_gateway.py", line 690, in start
    self.socket.connect((self.address, self.port))
  File "/usr/lib/python2.7/socket.py", line 224, in meth
    return getattr(self._sock,name)(*args)
error: [Errno 111] Connection refused
ERROR:An error occurred while trying to connect to the Java server
Traceback (most recent call last):
  File "/home/jduarte/Herramientas/spark/python/lib/py4j-0.9-src.zip/py4j/java_gateway.py", line 690, in start
    self.socket.connect((self.address, self.port))
  File "/usr/lib/python2.7/socket.py", line 224, in meth
    return getattr(self._sock,name)(*args)
error: [Errno 111] Connection refused
ERROR:An error occurred while trying to connect to the Java server
Traceback (most recent call last):
  File "/home/jduarte/Herramientas/spark/python/lib/py4j-0.9-src.zip/py4j/java_gateway.py", line 690, in start
    self.socket.connect((self.address, self.port))
  File "/usr/lib/python2.7/socket.py", line 224, in meth
    return getattr(self._sock,name)(*args)
error: [Errno 111] Connection refused
ERROR:An error occurred while trying to connect to the Java server
Traceback (most recent call last):
  File "/home/jduarte/Herramientas/spark/python/lib/py4j-0.9-src.zip/py4j/java_gateway.py", line 690, in start
    self.socket.connect((self.address, self.port))
  File "/usr/lib/python2.7/socket.py", line 224, in meth
    return getattr(self._sock,name)(*args)
error: [Errno 111] Connection refused
ERROR:An error occurred while trying to connect to the Java server
Traceback (most recent call last):
  File "/home/jduarte/Herramientas/spark/python/lib/py4j-0.9-src.zip/py4j/java_gateway.py", line 690, in start
    self.socket.connect((self.address, self.port))
  File "/usr/lib/python2.7/socket.py", line 224, in meth
    return getattr(self._sock,name)(*args)
error: [Errno 111] Connection refused
ERROR:An error occurred while trying to connect to the Java server
Traceback (most recent call last):
  File "/home/jduarte/Herramientas/spark/python/lib/py4j-0.9-src.zip/py4j/java_gateway.py", line 690, in start
    self.socket.connect((self.address, self.port))
  File "/usr/lib/python2.7/socket.py", line 224, in meth
    return getattr(self._sock,name)(*args)
error: [Errno 111] Connection refused
ERROR:An error occurred while trying to connect to the Java server
Traceback (most recent call last):
  File "/home/jduarte/Herramientas/spark/python/lib/py4j-0.9-src.zip/py4j/java_gateway.py", line 690, in start
    self.socket.connect((self.address, self.port))
  File "/usr/lib/python2.7/socket.py", line 224, in meth
    return getattr(self._sock,name)(*args)
error: [Errno 111] Connection refused
ERROR:An error occurred while trying to connect to the Java server
Traceback (most recent call last):
  File "/home/jduarte/Herramientas/spark/python/lib/py4j-0.9-src.zip/py4j/java_gateway.py", line 690, in start
    self.socket.connect((self.address, self.port))
  File "/usr/lib/python2.7/socket.py", line 224, in meth
    return getattr(self._sock,name)(*args)
error: [Errno 111] Connection refused
ERROR:An error occurred while trying to connect to the Java server
Traceback (most recent call last):
  File "/home/jduarte/Herramientas/spark/python/lib/py4j-0.9-src.zip/py4j/java_gateway.py", line 690, in start
    self.socket.connect((self.address, self.port))
  File "/usr/lib/python2.7/socket.py", line 224, in meth
    return getattr(self._sock,name)(*args)
error: [Errno 111] Connection refused
ERROR:An error occurred while trying to connect to the Java server
Traceback (most recent call last):
  File "/home/jduarte/Herramientas/spark/python/lib/py4j-0.9-src.zip/py4j/java_gateway.py", line 690, in start
    self.socket.connect((self.address, self.port))
  File "/usr/lib/python2.7/socket.py", line 224, in meth
    return getattr(self._sock,name)(*args)
error: [Errno 111] Connection refused
ERROR:An error occurred while trying to connect to the Java server
Traceback (most recent call last):
  File "/home/jduarte/Herramientas/spark/python/lib/py4j-0.9-src.zip/py4j/java_gateway.py", line 690, in start
    self.socket.connect((self.address, self.port))
  File "/usr/lib/python2.7/socket.py", line 224, in meth
    return getattr(self._sock,name)(*args)
error: [Errno 111] Connection refused
ERROR:An error occurred while trying to connect to the Java server
Traceback (most recent call last):
  File "/home/jduarte/Herramientas/spark/python/lib/py4j-0.9-src.zip/py4j/java_gateway.py", line 690, in start
    self.socket.connect((self.address, self.port))
  File "/usr/lib/python2.7/socket.py", line 224, in meth
    return getattr(self._sock,name)(*args)
error: [Errno 111] Connection refused
ERROR:An error occurred while trying to connect to the Java server
Traceback (most recent call last):
  File "/home/jduarte/Herramientas/spark/python/lib/py4j-0.9-src.zip/py4j/java_gateway.py", line 690, in start
    self.socket.connect((self.address, self.port))
  File "/usr/lib/python2.7/socket.py", line 224, in meth
    return getattr(self._sock,name)(*args)
error: [Errno 111] Connection refused
ERROR:An error occurred while trying to connect to the Java server
Traceback (most recent call last):
  File "/home/jduarte/Herramientas/spark/python/lib/py4j-0.9-src.zip/py4j/java_gateway.py", line 690, in start
    self.socket.connect((self.address, self.port))
  File "/usr/lib/python2.7/socket.py", line 224, in meth
    return getattr(self._sock,name)(*args)
error: [Errno 111] Connection refused
ERROR:An error occurred while trying to connect to the Java server
Traceback (most recent call last):
  File "/home/jduarte/Herramientas/spark/python/lib/py4j-0.9-src.zip/py4j/java_gateway.py", line 690, in start
    self.socket.connect((self.address, self.port))
  File "/usr/lib/python2.7/socket.py", line 224, in meth
    return getattr(self._sock,name)(*args)
error: [Errno 111] Connection refused
ERROR:An error occurred while trying to connect to the Java server
Traceback (most recent call last):
  File "/home/jduarte/Herramientas/spark/python/lib/py4j-0.9-src.zip/py4j/java_gateway.py", line 690, in start
    self.socket.connect((self.address, self.port))
  File "/usr/lib/python2.7/socket.py", line 224, in meth
    return getattr(self._sock,name)(*args)
error: [Errno 111] Connection refused
ERROR:An error occurred while trying to connect to the Java server
Traceback (most recent call last):
  File "/home/jduarte/Herramientas/spark/python/lib/py4j-0.9-src.zip/py4j/java_gateway.py", line 690, in start
    self.socket.connect((self.address, self.port))
  File "/usr/lib/python2.7/socket.py", line 224, in meth
    return getattr(self._sock,name)(*args)
error: [Errno 111] Connection refused
ERROR:An error occurred while trying to connect to the Java server
Traceback (most recent call last):
  File "/home/jduarte/Herramientas/spark/python/lib/py4j-0.9-src.zip/py4j/java_gateway.py", line 690, in start
    self.socket.connect((self.address, self.port))
  File "/usr/lib/python2.7/socket.py", line 224, in meth
    return getattr(self._sock,name)(*args)
error: [Errno 111] Connection refused
ERROR:An error occurred while trying to connect to the Java server
Traceback (most recent call last):
  File "/home/jduarte/Herramientas/spark/python/lib/py4j-0.9-src.zip/py4j/java_gateway.py", line 690, in start
    self.socket.connect((self.address, self.port))
  File "/usr/lib/python2.7/socket.py", line 224, in meth
    return getattr(self._sock,name)(*args)
error: [Errno 111] Connection refused
ERROR:An error occurred while trying to connect to the Java server
Traceback (most recent call last):
  File "/home/jduarte/Herramientas/spark/python/lib/py4j-0.9-src.zip/py4j/java_gateway.py", line 690, in start
    self.socket.connect((self.address, self.port))
  File "/usr/lib/python2.7/socket.py", line 224, in meth
    return getattr(self._sock,name)(*args)
error: [Errno 111] Connection refused
ERROR:An error occurred while trying to connect to the Java server
Traceback (most recent call last):
  File "/home/jduarte/Herramientas/spark/python/lib/py4j-0.9-src.zip/py4j/java_gateway.py", line 690, in start
    self.socket.connect((self.address, self.port))
  File "/usr/lib/python2.7/socket.py", line 224, in meth
    return getattr(self._sock,name)(*args)
error: [Errno 111] Connection refused
ERROR:An error occurred while trying to connect to the Java server
Traceback (most recent call last):
  File "/home/jduarte/Herramientas/spark/python/lib/py4j-0.9-src.zip/py4j/java_gateway.py", line 690, in start
    self.socket.connect((self.address, self.port))
  File "/usr/lib/python2.7/socket.py", line 224, in meth
    return getattr(self._sock,name)(*args)
error: [Errno 111] Connection refused
ERROR:An error occurred while trying to connect to the Java server
Traceback (most recent call last):
  File "/home/jduarte/Herramientas/spark/python/lib/py4j-0.9-src.zip/py4j/java_gateway.py", line 690, in start
    self.socket.connect((self.address, self.port))
  File "/usr/lib/python2.7/socket.py", line 224, in meth
    return getattr(self._sock,name)(*args)
error: [Errno 111] Connection refused
ERROR:An error occurred while trying to connect to the Java server
Traceback (most recent call last):
  File "/home/jduarte/Herramientas/spark/python/lib/py4j-0.9-src.zip/py4j/java_gateway.py", line 690, in start
    self.socket.connect((self.address, self.port))
  File "/usr/lib/python2.7/socket.py", line 224, in meth
    return getattr(self._sock,name)(*args)
error: [Errno 111] Connection refused
ERROR:An error occurred while trying to connect to the Java server
Traceback (most recent call last):
  File "/home/jduarte/Herramientas/spark/python/lib/py4j-0.9-src.zip/py4j/java_gateway.py", line 690, in start
    self.socket.connect((self.address, self.port))
  File "/usr/lib/python2.7/socket.py", line 224, in meth
    return getattr(self._sock,name)(*args)
error: [Errno 111] Connection refused
ERROR:An error occurred while trying to connect to the Java server
Traceback (most recent call last):
  File "/home/jduarte/Herramientas/spark/python/lib/py4j-0.9-src.zip/py4j/java_gateway.py", line 690, in start
    self.socket.connect((self.address, self.port))
  File "/usr/lib/python2.7/socket.py", line 224, in meth
    return getattr(self._sock,name)(*args)
error: [Errno 111] Connection refused
ERROR:An error occurred while trying to connect to the Java server
Traceback (most recent call last):
  File "/home/jduarte/Herramientas/spark/python/lib/py4j-0.9-src.zip/py4j/java_gateway.py", line 690, in start
    self.socket.connect((self.address, self.port))
  File "/usr/lib/python2.7/socket.py", line 224, in meth
    return getattr(self._sock,name)(*args)
error: [Errno 111] Connection refused
ERROR:An error occurred while trying to connect to the Java server
Traceback (most recent call last):
  File "/home/jduarte/Herramientas/spark/python/lib/py4j-0.9-src.zip/py4j/java_gateway.py", line 690, in start
    self.socket.connect((self.address, self.port))
  File "/usr/lib/python2.7/socket.py", line 224, in meth
    return getattr(self._sock,name)(*args)
error: [Errno 111] Connection refused
ERROR:An error occurred while trying to connect to the Java server
Traceback (most recent call last):
  File "/home/jduarte/Herramientas/spark/python/lib/py4j-0.9-src.zip/py4j/java_gateway.py", line 690, in start
    self.socket.connect((self.address, self.port))
  File "/usr/lib/python2.7/socket.py", line 224, in meth
    return getattr(self._sock,name)(*args)
error: [Errno 111] Connection refused
ERROR:An error occurred while trying to connect to the Java server
Traceback (most recent call last):
  File "/home/jduarte/Herramientas/spark/python/lib/py4j-0.9-src.zip/py4j/java_gateway.py", line 690, in start
    self.socket.connect((self.address, self.port))
  File "/usr/lib/python2.7/socket.py", line 224, in meth
    return getattr(self._sock,name)(*args)
error: [Errno 111] Connection refused
ERROR:An error occurred while trying to connect to the Java server
Traceback (most recent call last):
  File "/home/jduarte/Herramientas/spark/python/lib/py4j-0.9-src.zip/py4j/java_gateway.py", line 690, in start
    self.socket.connect((self.address, self.port))
  File "/usr/lib/python2.7/socket.py", line 224, in meth
    return getattr(self._sock,name)(*args)
error: [Errno 111] Connection refused
ERROR:An error occurred while trying to connect to the Java server
Traceback (most recent call last):
  File "/home/jduarte/Herramientas/spark/python/lib/py4j-0.9-src.zip/py4j/java_gateway.py", line 690, in start
    self.socket.connect((self.address, self.port))
  File "/usr/lib/python2.7/socket.py", line 224, in meth
    return getattr(self._sock,name)(*args)
error: [Errno 111] Connection refused
ERROR:An error occurred while trying to connect to the Java server
Traceback (most recent call last):
  File "/home/jduarte/Herramientas/spark/python/lib/py4j-0.9-src.zip/py4j/java_gateway.py", line 690, in start
    self.socket.connect((self.address, self.port))
  File "/usr/lib/python2.7/socket.py", line 224, in meth
    return getattr(self._sock,name)(*args)
error: [Errno 111] Connection refused
ERROR:An error occurred while trying to connect to the Java server
Traceback (most recent call last):
  File "/home/jduarte/Herramientas/spark/python/lib/py4j-0.9-src.zip/py4j/java_gateway.py", line 690, in start
    self.socket.connect((self.address, self.port))
  File "/usr/lib/python2.7/socket.py", line 224, in meth
    return getattr(self._sock,name)(*args)
error: [Errno 111] Connection refused
ERROR:An error occurred while trying to connect to the Java server
Traceback (most recent call last):
  File "/home/jduarte/Herramientas/spark/python/lib/py4j-0.9-src.zip/py4j/java_gateway.py", line 690, in start
    self.socket.connect((self.address, self.port))
  File "/usr/lib/python2.7/socket.py", line 224, in meth
    return getattr(self._sock,name)(*args)
error: [Errno 111] Connection refused
ERROR:An error occurred while trying to connect to the Java server
Traceback (most recent call last):
  File "/home/jduarte/Herramientas/spark/python/lib/py4j-0.9-src.zip/py4j/java_gateway.py", line 690, in start
    self.socket.connect((self.address, self.port))
  File "/usr/lib/python2.7/socket.py", line 224, in meth
    return getattr(self._sock,name)(*args)
error: [Errno 111] Connection refused
ERROR:An error occurred while trying to connect to the Java server
Traceback (most recent call last):
  File "/home/jduarte/Herramientas/spark/python/lib/py4j-0.9-src.zip/py4j/java_gateway.py", line 690, in start
    self.socket.connect((self.address, self.port))
  File "/usr/lib/python2.7/socket.py", line 224, in meth
    return getattr(self._sock,name)(*args)
error: [Errno 111] Connection refused
ERROR:An error occurred while trying to connect to the Java server
Traceback (most recent call last):
  File "/home/jduarte/Herramientas/spark/python/lib/py4j-0.9-src.zip/py4j/java_gateway.py", line 690, in start
    self.socket.connect((self.address, self.port))
  File "/usr/lib/python2.7/socket.py", line 224, in meth
    return getattr(self._sock,name)(*args)
error: [Errno 111] Connection refused
ERROR:An error occurred while trying to connect to the Java server
Traceback (most recent call last):
  File "/home/jduarte/Herramientas/spark/python/lib/py4j-0.9-src.zip/py4j/java_gateway.py", line 690, in start
    self.socket.connect((self.address, self.port))
  File "/usr/lib/python2.7/socket.py", line 224, in meth
    return getattr(self._sock,name)(*args)
error: [Errno 111] Connection refused
ERROR:An error occurred while trying to connect to the Java server
Traceback (most recent call last):
  File "/home/jduarte/Herramientas/spark/python/lib/py4j-0.9-src.zip/py4j/java_gateway.py", line 690, in start
    self.socket.connect((self.address, self.port))
  File "/usr/lib/python2.7/socket.py", line 224, in meth
    return getattr(self._sock,name)(*args)
error: [Errno 111] Connection refused
ERROR:An error occurred while trying to connect to the Java server
Traceback (most recent call last):
  File "/home/jduarte/Herramientas/spark/python/lib/py4j-0.9-src.zip/py4j/java_gateway.py", line 690, in start
    self.socket.connect((self.address, self.port))
  File "/usr/lib/python2.7/socket.py", line 224, in meth
    return getattr(self._sock,name)(*args)
error: [Errno 111] Connection refused
ERROR:An error occurred while trying to connect to the Java server
Traceback (most recent call last):
  File "/home/jduarte/Herramientas/spark/python/lib/py4j-0.9-src.zip/py4j/java_gateway.py", line 690, in start
    self.socket.connect((self.address, self.port))
  File "/usr/lib/python2.7/socket.py", line 224, in meth
    return getattr(self._sock,name)(*args)
error: [Errno 111] Connection refused
ERROR:An error occurred while trying to connect to the Java server
Traceback (most recent call last):
  File "/home/jduarte/Herramientas/spark/python/lib/py4j-0.9-src.zip/py4j/java_gateway.py", line 690, in start
    self.socket.connect((self.address, self.port))
  File "/usr/lib/python2.7/socket.py", line 224, in meth
    return getattr(self._sock,name)(*args)
error: [Errno 111] Connection refused
ERROR:An error occurred while trying to connect to the Java server
Traceback (most recent call last):
  File "/home/jduarte/Herramientas/spark/python/lib/py4j-0.9-src.zip/py4j/java_gateway.py", line 690, in start
    self.socket.connect((self.address, self.port))
  File "/usr/lib/python2.7/socket.py", line 224, in meth
    return getattr(self._sock,name)(*args)
error: [Errno 111] Connection refused
ERROR:An error occurred while trying to connect to the Java server
Traceback (most recent call last):
  File "/home/jduarte/Herramientas/spark/python/lib/py4j-0.9-src.zip/py4j/java_gateway.py", line 690, in start
    self.socket.connect((self.address, self.port))
  File "/usr/lib/python2.7/socket.py", line 224, in meth
    return getattr(self._sock,name)(*args)
error: [Errno 111] Connection refused
ERROR:An error occurred while trying to connect to the Java server
Traceback (most recent call last):
  File "/home/jduarte/Herramientas/spark/python/lib/py4j-0.9-src.zip/py4j/java_gateway.py", line 690, in start
    self.socket.connect((self.address, self.port))
  File "/usr/lib/python2.7/socket.py", line 224, in meth
    return getattr(self._sock,name)(*args)
error: [Errno 111] Connection refused
ERROR:An error occurred while trying to connect to the Java server
Traceback (most recent call last):
  File "/home/jduarte/Herramientas/spark/python/lib/py4j-0.9-src.zip/py4j/java_gateway.py", line 690, in start
    self.socket.connect((self.address, self.port))
  File "/usr/lib/python2.7/socket.py", line 224, in meth
    return getattr(self._sock,name)(*args)
error: [Errno 111] Connection refused
ERROR:An error occurred while trying to connect to the Java server
Traceback (most recent call last):
  File "/home/jduarte/Herramientas/spark/python/lib/py4j-0.9-src.zip/py4j/java_gateway.py", line 690, in start
    self.socket.connect((self.address, self.port))
  File "/usr/lib/python2.7/socket.py", line 224, in meth
    return getattr(self._sock,name)(*args)
error: [Errno 111] Connection refused
ERROR:An error occurred while trying to connect to the Java server
Traceback (most recent call last):
  File "/home/jduarte/Herramientas/spark/python/lib/py4j-0.9-src.zip/py4j/java_gateway.py", line 690, in start
    self.socket.connect((self.address, self.port))
  File "/usr/lib/python2.7/socket.py", line 224, in meth
    return getattr(self._sock,name)(*args)
error: [Errno 111] Connection refused
ERROR:An error occurred while trying to connect to the Java server
Traceback (most recent call last):
  File "/home/jduarte/Herramientas/spark/python/lib/py4j-0.9-src.zip/py4j/java_gateway.py", line 690, in start
    self.socket.connect((self.address, self.port))
  File "/usr/lib/python2.7/socket.py", line 224, in meth
    return getattr(self._sock,name)(*args)
error: [Errno 111] Connection refused
ERROR:An error occurred while trying to connect to the Java server
Traceback (most recent call last):
  File "/home/jduarte/Herramientas/spark/python/lib/py4j-0.9-src.zip/py4j/java_gateway.py", line 690, in start
    self.socket.connect((self.address, self.port))
  File "/usr/lib/python2.7/socket.py", line 224, in meth
    return getattr(self._sock,name)(*args)
error: [Errno 111] Connection refused
ERROR:An error occurred while trying to connect to the Java server
Traceback (most recent call last):
  File "/home/jduarte/Herramientas/spark/python/lib/py4j-0.9-src.zip/py4j/java_gateway.py", line 690, in start
    self.socket.connect((self.address, self.port))
  File "/usr/lib/python2.7/socket.py", line 224, in meth
    return getattr(self._sock,name)(*args)
error: [Errno 111] Connection refused
ERROR:An error occurred while trying to connect to the Java server
Traceback (most recent call last):
  File "/home/jduarte/Herramientas/spark/python/lib/py4j-0.9-src.zip/py4j/java_gateway.py", line 690, in start
    self.socket.connect((self.address, self.port))
  File "/usr/lib/python2.7/socket.py", line 224, in meth
    return getattr(self._sock,name)(*args)
error: [Errno 111] Connection refused
ERROR:An error occurred while trying to connect to the Java server
Traceback (most recent call last):
  File "/home/jduarte/Herramientas/spark/python/lib/py4j-0.9-src.zip/py4j/java_gateway.py", line 690, in start
    self.socket.connect((self.address, self.port))
  File "/usr/lib/python2.7/socket.py", line 224, in meth
    return getattr(self._sock,name)(*args)
error: [Errno 111] Connection refused
ERROR:An error occurred while trying to connect to the Java server
Traceback (most recent call last):
  File "/home/jduarte/Herramientas/spark/python/lib/py4j-0.9-src.zip/py4j/java_gateway.py", line 690, in start
    self.socket.connect((self.address, self.port))
  File "/usr/lib/python2.7/socket.py", line 224, in meth
    return getattr(self._sock,name)(*args)
error: [Errno 111] Connection refused
ERROR:An error occurred while trying to connect to the Java server
Traceback (most recent call last):
  File "/home/jduarte/Herramientas/spark/python/lib/py4j-0.9-src.zip/py4j/java_gateway.py", line 690, in start
    self.socket.connect((self.address, self.port))
  File "/usr/lib/python2.7/socket.py", line 224, in meth
    return getattr(self._sock,name)(*args)
error: [Errno 111] Connection refused
ERROR:An error occurred while trying to connect to the Java server
Traceback (most recent call last):
  File "/home/jduarte/Herramientas/spark/python/lib/py4j-0.9-src.zip/py4j/java_gateway.py", line 690, in start
    self.socket.connect((self.address, self.port))
  File "/usr/lib/python2.7/socket.py", line 224, in meth
    return getattr(self._sock,name)(*args)
error: [Errno 111] Connection refused
ERROR:An error occurred while trying to connect to the Java server
Traceback (most recent call last):
  File "/home/jduarte/Herramientas/spark/python/lib/py4j-0.9-src.zip/py4j/java_gateway.py", line 690, in start
    self.socket.connect((self.address, self.port))
  File "/usr/lib/python2.7/socket.py", line 224, in meth
    return getattr(self._sock,name)(*args)
error: [Errno 111] Connection refused
ERROR:An error occurred while trying to connect to the Java server
Traceback (most recent call last):
  File "/home/jduarte/Herramientas/spark/python/lib/py4j-0.9-src.zip/py4j/java_gateway.py", line 690, in start
    self.socket.connect((self.address, self.port))
  File "/usr/lib/python2.7/socket.py", line 224, in meth
    return getattr(self._sock,name)(*args)
error: [Errno 111] Connection refused
ERROR:An error occurred while trying to connect to the Java server
Traceback (most recent call last):
  File "/home/jduarte/Herramientas/spark/python/lib/py4j-0.9-src.zip/py4j/java_gateway.py", line 690, in start
    self.socket.connect((self.address, self.port))
  File "/usr/lib/python2.7/socket.py", line 224, in meth
    return getattr(self._sock,name)(*args)
error: [Errno 111] Connection refused
ERROR:An error occurred while trying to connect to the Java server
Traceback (most recent call last):
  File "/home/jduarte/Herramientas/spark/python/lib/py4j-0.9-src.zip/py4j/java_gateway.py", line 690, in start
    self.socket.connect((self.address, self.port))
  File "/usr/lib/python2.7/socket.py", line 224, in meth
    return getattr(self._sock,name)(*args)
error: [Errno 111] Connection refused
ERROR:An error occurred while trying to connect to the Java server
Traceback (most recent call last):
  File "/home/jduarte/Herramientas/spark/python/lib/py4j-0.9-src.zip/py4j/java_gateway.py", line 690, in start
    self.socket.connect((self.address, self.port))
  File "/usr/lib/python2.7/socket.py", line 224, in meth
    return getattr(self._sock,name)(*args)
error: [Errno 111] Connection refused
ERROR:An error occurred while trying to connect to the Java server
Traceback (most recent call last):
  File "/home/jduarte/Herramientas/spark/python/lib/py4j-0.9-src.zip/py4j/java_gateway.py", line 690, in start
    self.socket.connect((self.address, self.port))
  File "/usr/lib/python2.7/socket.py", line 224, in meth
    return getattr(self._sock,name)(*args)
error: [Errno 111] Connection refused
ERROR:An error occurred while trying to connect to the Java server
Traceback (most recent call last):
  File "/home/jduarte/Herramientas/spark/python/lib/py4j-0.9-src.zip/py4j/java_gateway.py", line 690, in start
    self.socket.connect((self.address, self.port))
  File "/usr/lib/python2.7/socket.py", line 224, in meth
    return getattr(self._sock,name)(*args)
error: [Errno 111] Connection refused
ERROR:An error occurred while trying to connect to the Java server
Traceback (most recent call last):
  File "/home/jduarte/Herramientas/spark/python/lib/py4j-0.9-src.zip/py4j/java_gateway.py", line 690, in start
    self.socket.connect((self.address, self.port))
  File "/usr/lib/python2.7/socket.py", line 224, in meth
    return getattr(self._sock,name)(*args)
error: [Errno 111] Connection refused
ERROR:An error occurred while trying to connect to the Java server
Traceback (most recent call last):
  File "/home/jduarte/Herramientas/spark/python/lib/py4j-0.9-src.zip/py4j/java_gateway.py", line 690, in start
    self.socket.connect((self.address, self.port))
  File "/usr/lib/python2.7/socket.py", line 224, in meth
    return getattr(self._sock,name)(*args)
error: [Errno 111] Connection refused
ERROR:An error occurred while trying to connect to the Java server
Traceback (most recent call last):
  File "/home/jduarte/Herramientas/spark/python/lib/py4j-0.9-src.zip/py4j/java_gateway.py", line 690, in start
    self.socket.connect((self.address, self.port))
  File "/usr/lib/python2.7/socket.py", line 224, in meth
    return getattr(self._sock,name)(*args)
error: [Errno 111] Connection refused
ERROR:An error occurred while trying to connect to the Java server
Traceback (most recent call last):
  File "/home/jduarte/Herramientas/spark/python/lib/py4j-0.9-src.zip/py4j/java_gateway.py", line 690, in start
    self.socket.connect((self.address, self.port))
  File "/usr/lib/python2.7/socket.py", line 224, in meth
    return getattr(self._sock,name)(*args)
error: [Errno 111] Connection refused
ERROR:An error occurred while trying to connect to the Java server
Traceback (most recent call last):
  File "/home/jduarte/Herramientas/spark/python/lib/py4j-0.9-src.zip/py4j/java_gateway.py", line 690, in start
    self.socket.connect((self.address, self.port))
  File "/usr/lib/python2.7/socket.py", line 224, in meth
    return getattr(self._sock,name)(*args)
error: [Errno 111] Connection refused
ERROR:An error occurred while trying to connect to the Java server
Traceback (most recent call last):
  File "/home/jduarte/Herramientas/spark/python/lib/py4j-0.9-src.zip/py4j/java_gateway.py", line 690, in start
    self.socket.connect((self.address, self.port))
  File "/usr/lib/python2.7/socket.py", line 224, in meth
    return getattr(self._sock,name)(*args)
error: [Errno 111] Connection refused
ERROR:An error occurred while trying to connect to the Java server
Traceback (most recent call last):
  File "/home/jduarte/Herramientas/spark/python/lib/py4j-0.9-src.zip/py4j/java_gateway.py", line 690, in start
    self.socket.connect((self.address, self.port))
  File "/usr/lib/python2.7/socket.py", line 224, in meth
    return getattr(self._sock,name)(*args)
error: [Errno 111] Connection refused
ERROR:An error occurred while trying to connect to the Java server
Traceback (most recent call last):
  File "/home/jduarte/Herramientas/spark/python/lib/py4j-0.9-src.zip/py4j/java_gateway.py", line 690, in start
    self.socket.connect((self.address, self.port))
  File "/usr/lib/python2.7/socket.py", line 224, in meth
    return getattr(self._sock,name)(*args)
error: [Errno 111] Connection refused
ERROR:An error occurred while trying to connect to the Java server
Traceback (most recent call last):
  File "/home/jduarte/Herramientas/spark/python/lib/py4j-0.9-src.zip/py4j/java_gateway.py", line 690, in start
    self.socket.connect((self.address, self.port))
  File "/usr/lib/python2.7/socket.py", line 224, in meth
    return getattr(self._sock,name)(*args)
error: [Errno 111] Connection refused
ERROR:An error occurred while trying to connect to the Java server
Traceback (most recent call last):
  File "/home/jduarte/Herramientas/spark/python/lib/py4j-0.9-src.zip/py4j/java_gateway.py", line 690, in start
    self.socket.connect((self.address, self.port))
  File "/usr/lib/python2.7/socket.py", line 224, in meth
    return getattr(self._sock,name)(*args)
error: [Errno 111] Connection refused
ERROR:An error occurred while trying to connect to the Java server
Traceback (most recent call last):
  File "/home/jduarte/Herramientas/spark/python/lib/py4j-0.9-src.zip/py4j/java_gateway.py", line 690, in start
    self.socket.connect((self.address, self.port))
  File "/usr/lib/python2.7/socket.py", line 224, in meth
    return getattr(self._sock,name)(*args)
error: [Errno 111] Connection refused
ERROR:An error occurred while trying to connect to the Java server
Traceback (most recent call last):
  File "/home/jduarte/Herramientas/spark/python/lib/py4j-0.9-src.zip/py4j/java_gateway.py", line 690, in start
    self.socket.connect((self.address, self.port))
  File "/usr/lib/python2.7/socket.py", line 224, in meth
    return getattr(self._sock,name)(*args)
error: [Errno 111] Connection refused
ERROR:An error occurred while trying to connect to the Java server
Traceback (most recent call last):
  File "/home/jduarte/Herramientas/spark/python/lib/py4j-0.9-src.zip/py4j/java_gateway.py", line 690, in start
    self.socket.connect((self.address, self.port))
  File "/usr/lib/python2.7/socket.py", line 224, in meth
    return getattr(self._sock,name)(*args)
error: [Errno 111] Connection refused
ERROR:An error occurred while trying to connect to the Java server
Traceback (most recent call last):
  File "/home/jduarte/Herramientas/spark/python/lib/py4j-0.9-src.zip/py4j/java_gateway.py", line 690, in start
    self.socket.connect((self.address, self.port))
  File "/usr/lib/python2.7/socket.py", line 224, in meth
    return getattr(self._sock,name)(*args)
error: [Errno 111] Connection refused
ERROR:An error occurred while trying to connect to the Java server
Traceback (most recent call last):
  File "/home/jduarte/Herramientas/spark/python/lib/py4j-0.9-src.zip/py4j/java_gateway.py", line 690, in start
    self.socket.connect((self.address, self.port))
  File "/usr/lib/python2.7/socket.py", line 224, in meth
    return getattr(self._sock,name)(*args)
error: [Errno 111] Connection refused
ERROR:An error occurred while trying to connect to the Java server
Traceback (most recent call last):
  File "/home/jduarte/Herramientas/spark/python/lib/py4j-0.9-src.zip/py4j/java_gateway.py", line 690, in start
    self.socket.connect((self.address, self.port))
  File "/usr/lib/python2.7/socket.py", line 224, in meth
    return getattr(self._sock,name)(*args)
error: [Errno 111] Connection refused
ERROR:An error occurred while trying to connect to the Java server
Traceback (most recent call last):
  File "/home/jduarte/Herramientas/spark/python/lib/py4j-0.9-src.zip/py4j/java_gateway.py", line 690, in start
    self.socket.connect((self.address, self.port))
  File "/usr/lib/python2.7/socket.py", line 224, in meth
    return getattr(self._sock,name)(*args)
error: [Errno 111] Connection refused
ERROR:An error occurred while trying to connect to the Java server
Traceback (most recent call last):
  File "/home/jduarte/Herramientas/spark/python/lib/py4j-0.9-src.zip/py4j/java_gateway.py", line 690, in start
    self.socket.connect((self.address, self.port))
  File "/usr/lib/python2.7/socket.py", line 224, in meth
    return getattr(self._sock,name)(*args)
error: [Errno 111] Connection refused
ERROR:An error occurred while trying to connect to the Java server
Traceback (most recent call last):
  File "/home/jduarte/Herramientas/spark/python/lib/py4j-0.9-src.zip/py4j/java_gateway.py", line 690, in start
    self.socket.connect((self.address, self.port))
  File "/usr/lib/python2.7/socket.py", line 224, in meth
    return getattr(self._sock,name)(*args)
error: [Errno 111] Connection refused
ERROR:An error occurred while trying to connect to the Java server
Traceback (most recent call last):
  File "/home/jduarte/Herramientas/spark/python/lib/py4j-0.9-src.zip/py4j/java_gateway.py", line 690, in start
    self.socket.connect((self.address, self.port))
  File "/usr/lib/python2.7/socket.py", line 224, in meth
    return getattr(self._sock,name)(*args)
error: [Errno 111] Connection refused
ERROR:An error occurred while trying to connect to the Java server
Traceback (most recent call last):
  File "/home/jduarte/Herramientas/spark/python/lib/py4j-0.9-src.zip/py4j/java_gateway.py", line 690, in start
    self.socket.connect((self.address, self.port))
  File "/usr/lib/python2.7/socket.py", line 224, in meth
    return getattr(self._sock,name)(*args)
error: [Errno 111] Connection refused
ERROR:An error occurred while trying to connect to the Java server
Traceback (most recent call last):
  File "/home/jduarte/Herramientas/spark/python/lib/py4j-0.9-src.zip/py4j/java_gateway.py", line 690, in start
    self.socket.connect((self.address, self.port))
  File "/usr/lib/python2.7/socket.py", line 224, in meth
    return getattr(self._sock,name)(*args)
error: [Errno 111] Connection refused
ERROR:An error occurred while trying to connect to the Java server
Traceback (most recent call last):
  File "/home/jduarte/Herramientas/spark/python/lib/py4j-0.9-src.zip/py4j/java_gateway.py", line 690, in start
    self.socket.connect((self.address, self.port))
  File "/usr/lib/python2.7/socket.py", line 224, in meth
    return getattr(self._sock,name)(*args)
error: [Errno 111] Connection refused
ERROR:An error occurred while trying to connect to the Java server
Traceback (most recent call last):
  File "/home/jduarte/Herramientas/spark/python/lib/py4j-0.9-src.zip/py4j/java_gateway.py", line 690, in start
    self.socket.connect((self.address, self.port))
  File "/usr/lib/python2.7/socket.py", line 224, in meth
    return getattr(self._sock,name)(*args)
error: [Errno 111] Connection refused
ERROR:An error occurred while trying to connect to the Java server
Traceback (most recent call last):
  File "/home/jduarte/Herramientas/spark/python/lib/py4j-0.9-src.zip/py4j/java_gateway.py", line 690, in start
    self.socket.connect((self.address, self.port))
  File "/usr/lib/python2.7/socket.py", line 224, in meth
    return getattr(self._sock,name)(*args)
error: [Errno 111] Connection refused
ERROR:An error occurred while trying to connect to the Java server
Traceback (most recent call last):
  File "/home/jduarte/Herramientas/spark/python/lib/py4j-0.9-src.zip/py4j/java_gateway.py", line 690, in start
    self.socket.connect((self.address, self.port))
  File "/usr/lib/python2.7/socket.py", line 224, in meth
    return getattr(self._sock,name)(*args)
error: [Errno 111] Connection refused
ERROR:An error occurred while trying to connect to the Java server
Traceback (most recent call last):
  File "/home/jduarte/Herramientas/spark/python/lib/py4j-0.9-src.zip/py4j/java_gateway.py", line 690, in start
    self.socket.connect((self.address, self.port))
  File "/usr/lib/python2.7/socket.py", line 224, in meth
    return getattr(self._sock,name)(*args)
error: [Errno 111] Connection refused
ERROR:An error occurred while trying to connect to the Java server
Traceback (most recent call last):
  File "/home/jduarte/Herramientas/spark/python/lib/py4j-0.9-src.zip/py4j/java_gateway.py", line 690, in start
    self.socket.connect((self.address, self.port))
  File "/usr/lib/python2.7/socket.py", line 224, in meth
    return getattr(self._sock,name)(*args)
error: [Errno 111] Connection refused
ERROR:An error occurred while trying to connect to the Java server
Traceback (most recent call last):
  File "/home/jduarte/Herramientas/spark/python/lib/py4j-0.9-src.zip/py4j/java_gateway.py", line 690, in start
    self.socket.connect((self.address, self.port))
  File "/usr/lib/python2.7/socket.py", line 224, in meth
    return getattr(self._sock,name)(*args)
error: [Errno 111] Connection refused
ERROR:An error occurred while trying to connect to the Java server
Traceback (most recent call last):
  File "/home/jduarte/Herramientas/spark/python/lib/py4j-0.9-src.zip/py4j/java_gateway.py", line 690, in start
    self.socket.connect((self.address, self.port))
  File "/usr/lib/python2.7/socket.py", line 224, in meth
    return getattr(self._sock,name)(*args)
error: [Errno 111] Connection refused
ERROR:An error occurred while trying to connect to the Java server
Traceback (most recent call last):
  File "/home/jduarte/Herramientas/spark/python/lib/py4j-0.9-src.zip/py4j/java_gateway.py", line 690, in start
    self.socket.connect((self.address, self.port))
  File "/usr/lib/python2.7/socket.py", line 224, in meth
    return getattr(self._sock,name)(*args)
error: [Errno 111] Connection refused
ERROR:An error occurred while trying to connect to the Java server
Traceback (most recent call last):
  File "/home/jduarte/Herramientas/spark/python/lib/py4j-0.9-src.zip/py4j/java_gateway.py", line 690, in start
    self.socket.connect((self.address, self.port))
  File "/usr/lib/python2.7/socket.py", line 224, in meth
    return getattr(self._sock,name)(*args)
error: [Errno 111] Connection refused
ERROR:An error occurred while trying to connect to the Java server
Traceback (most recent call last):
  File "/home/jduarte/Herramientas/spark/python/lib/py4j-0.9-src.zip/py4j/java_gateway.py", line 690, in start
    self.socket.connect((self.address, self.port))
  File "/usr/lib/python2.7/socket.py", line 224, in meth
    return getattr(self._sock,name)(*args)
error: [Errno 111] Connection refused
ERROR:An error occurred while trying to connect to the Java server
Traceback (most recent call last):
  File "/home/jduarte/Herramientas/spark/python/lib/py4j-0.9-src.zip/py4j/java_gateway.py", line 690, in start
    self.socket.connect((self.address, self.port))
  File "/usr/lib/python2.7/socket.py", line 224, in meth
    return getattr(self._sock,name)(*args)
error: [Errno 111] Connection refused
ERROR:An error occurred while trying to connect to the Java server
Traceback (most recent call last):
  File "/home/jduarte/Herramientas/spark/python/lib/py4j-0.9-src.zip/py4j/java_gateway.py", line 690, in start
    self.socket.connect((self.address, self.port))
  File "/usr/lib/python2.7/socket.py", line 224, in meth
    return getattr(self._sock,name)(*args)
error: [Errno 111] Connection refused
ERROR:An error occurred while trying to connect to the Java server
Traceback (most recent call last):
  File "/home/jduarte/Herramientas/spark/python/lib/py4j-0.9-src.zip/py4j/java_gateway.py", line 690, in start
    self.socket.connect((self.address, self.port))
  File "/usr/lib/python2.7/socket.py", line 224, in meth
    return getattr(self._sock,name)(*args)
error: [Errno 111] Connection refused
ERROR:An error occurred while trying to connect to the Java server
Traceback (most recent call last):
  File "/home/jduarte/Herramientas/spark/python/lib/py4j-0.9-src.zip/py4j/java_gateway.py", line 690, in start
    self.socket.connect((self.address, self.port))
  File "/usr/lib/python2.7/socket.py", line 224, in meth
    return getattr(self._sock,name)(*args)
error: [Errno 111] Connection refused
ERROR:An error occurred while trying to connect to the Java server
Traceback (most recent call last):
  File "/home/jduarte/Herramientas/spark/python/lib/py4j-0.9-src.zip/py4j/java_gateway.py", line 690, in start
    self.socket.connect((self.address, self.port))
  File "/usr/lib/python2.7/socket.py", line 224, in meth
    return getattr(self._sock,name)(*args)
error: [Errno 111] Connection refused
ERROR:An error occurred while trying to connect to the Java server
Traceback (most recent call last):
  File "/home/jduarte/Herramientas/spark/python/lib/py4j-0.9-src.zip/py4j/java_gateway.py", line 690, in start
    self.socket.connect((self.address, self.port))
  File "/usr/lib/python2.7/socket.py", line 224, in meth
    return getattr(self._sock,name)(*args)
error: [Errno 111] Connection refused
ERROR:An error occurred while trying to connect to the Java server
Traceback (most recent call last):
  File "/home/jduarte/Herramientas/spark/python/lib/py4j-0.9-src.zip/py4j/java_gateway.py", line 690, in start
    self.socket.connect((self.address, self.port))
  File "/usr/lib/python2.7/socket.py", line 224, in meth
    return getattr(self._sock,name)(*args)
error: [Errno 111] Connection refused
ERROR:An error occurred while trying to connect to the Java server
Traceback (most recent call last):
  File "/home/jduarte/Herramientas/spark/python/lib/py4j-0.9-src.zip/py4j/java_gateway.py", line 690, in start
    self.socket.connect((self.address, self.port))
  File "/usr/lib/python2.7/socket.py", line 224, in meth
    return getattr(self._sock,name)(*args)
error: [Errno 111] Connection refused
ERROR:An error occurred while trying to connect to the Java server
Traceback (most recent call last):
  File "/home/jduarte/Herramientas/spark/python/lib/py4j-0.9-src.zip/py4j/java_gateway.py", line 690, in start
    self.socket.connect((self.address, self.port))
  File "/usr/lib/python2.7/socket.py", line 224, in meth
    return getattr(self._sock,name)(*args)
error: [Errno 111] Connection refused
ERROR:An error occurred while trying to connect to the Java server
Traceback (most recent call last):
  File "/home/jduarte/Herramientas/spark/python/lib/py4j-0.9-src.zip/py4j/java_gateway.py", line 690, in start
    self.socket.connect((self.address, self.port))
  File "/usr/lib/python2.7/socket.py", line 224, in meth
    return getattr(self._sock,name)(*args)
error: [Errno 111] Connection refused
ERROR:An error occurred while trying to connect to the Java server
Traceback (most recent call last):
  File "/home/jduarte/Herramientas/spark/python/lib/py4j-0.9-src.zip/py4j/java_gateway.py", line 690, in start
    self.socket.connect((self.address, self.port))
  File "/usr/lib/python2.7/socket.py", line 224, in meth
    return getattr(self._sock,name)(*args)
error: [Errno 111] Connection refused
ERROR:An error occurred while trying to connect to the Java server
Traceback (most recent call last):
  File "/home/jduarte/Herramientas/spark/python/lib/py4j-0.9-src.zip/py4j/java_gateway.py", line 690, in start
    self.socket.connect((self.address, self.port))
  File "/usr/lib/python2.7/socket.py", line 224, in meth
    return getattr(self._sock,name)(*args)
error: [Errno 111] Connection refused
ERROR:An error occurred while trying to connect to the Java server
Traceback (most recent call last):
  File "/home/jduarte/Herramientas/spark/python/lib/py4j-0.9-src.zip/py4j/java_gateway.py", line 690, in start
    self.socket.connect((self.address, self.port))
  File "/usr/lib/python2.7/socket.py", line 224, in meth
    return getattr(self._sock,name)(*args)
error: [Errno 111] Connection refused
INFO:Calentando motores...
INFO:[13/Jun/2016:19:29:16] ENGINE Bus STARTING
INFO:[13/Jun/2016:19:29:16] ENGINE Started monitor thread '_TimeoutMonitor'.
INFO:[13/Jun/2016:19:29:16] ENGINE Started monitor thread 'Autoreloader'.
INFO:[13/Jun/2016:19:29:16] ENGINE Serving on http://0.0.0.0:5432
INFO:[13/Jun/2016:19:29:16] ENGINE Bus STARTED
INFO:Cargando arhcivos...
INFO:Calculando features para tweets...
INFO:Iniciando calculo de tweets por dia...
INFO:Iniciando calculo de tweets por hora...
INFO:Iniciando exploracion de las fuentes de los tweets...
INFO:Iniciando calculo de diversidad lexicografica...
INFO:Iniciando calculo del promedio de la longuitud de los tweets...
INFO:Iniciando calculo del ratio de respuestas...
INFO:Iniciando calculo del promedio de los hashtags...
INFO:Iniciando calculo del promedio de menciones...
INFO:Iniciando calculo del promedio de palabras por tweet...
INFO:Iniciando calculo del promedio de diversidad de palabras...
INFO:Iniciando calculo del ratio de urls...
INFO:Registrando tablas...
INFO:Join entre tweets...
INFO:Calculando features para usuarios...
INFO:Realizando join de usuarios con tweets...
INFO:Finalizado el join...
ERROR:Exception on /evaluar/ [POST]
Traceback (most recent call last):
  File "/usr/local/lib/python2.7/dist-packages/flask/app.py", line 1817, in wsgi_app
    response = self.full_dispatch_request()
  File "/usr/local/lib/python2.7/dist-packages/flask/app.py", line 1477, in full_dispatch_request
    rv = self.handle_user_exception(e)
  File "/usr/local/lib/python2.7/dist-packages/flask/app.py", line 1381, in handle_user_exception
    reraise(exc_type, exc_value, tb)
  File "/usr/local/lib/python2.7/dist-packages/flask/app.py", line 1475, in full_dispatch_request
    rv = self.dispatch_request()
  File "/usr/local/lib/python2.7/dist-packages/flask/app.py", line 1461, in dispatch_request
    return self.view_functions[rule.endpoint](**req.view_args)
  File "/home/jduarte/Workspace/TesisSpark/app.py", line 33, in evaluar
    resultado = motor_clasificador.evaluar(directorio)
  File "/home/jduarte/Workspace/TesisSpark/engine.py", line 183, in evaluar
    resultado = modelo.predict(features)
AttributeError: 'RDD' object has no attribute 'predict'
INFO:[13/Jun/2016:19:30:55] ENGINE Keyboard Interrupt: shutting down bus
INFO:[13/Jun/2016:19:30:55] ENGINE Bus STOPPING
INFO:[13/Jun/2016:19:30:55] ENGINE HTTP Server cherrypy._cpwsgi_server.CPWSGIServer(('0.0.0.0', 5432)) shut down
INFO:[13/Jun/2016:19:30:55] ENGINE Stopped thread 'Autoreloader'.
INFO:[13/Jun/2016:19:30:55] ENGINE Stopped thread '_TimeoutMonitor'.
INFO:[13/Jun/2016:19:30:55] ENGINE Bus STOPPED
INFO:[13/Jun/2016:19:30:55] ENGINE Bus EXITING
INFO:[13/Jun/2016:19:30:55] ENGINE Bus EXITED
INFO:[13/Jun/2016:19:30:55] ENGINE Waiting for child threads to terminate...
INFO:Calentando motores...
INFO:[13/Jun/2016:19:31:24] ENGINE Bus STARTING
INFO:[13/Jun/2016:19:31:24] ENGINE Started monitor thread '_TimeoutMonitor'.
INFO:[13/Jun/2016:19:31:24] ENGINE Started monitor thread 'Autoreloader'.
INFO:[13/Jun/2016:19:31:24] ENGINE Serving on http://0.0.0.0:5432
INFO:[13/Jun/2016:19:31:24] ENGINE Bus STARTED
INFO:Cargando arhcivos...
INFO:Calculando features para tweets...
INFO:Iniciando calculo de tweets por dia...
INFO:Iniciando calculo de tweets por hora...
INFO:Iniciando exploracion de las fuentes de los tweets...
INFO:Iniciando calculo de diversidad lexicografica...
INFO:Iniciando calculo del promedio de la longuitud de los tweets...
INFO:Iniciando calculo del ratio de respuestas...
INFO:Iniciando calculo del promedio de los hashtags...
INFO:Iniciando calculo del promedio de menciones...
INFO:Iniciando calculo del promedio de palabras por tweet...
INFO:Iniciando calculo del promedio de diversidad de palabras...
INFO:Iniciando calculo del ratio de urls...
INFO:Registrando tablas...
INFO:Join entre tweets...
INFO:Calculando features para usuarios...
INFO:Realizando join de usuarios con tweets...
INFO:Finalizado el join...
INFO:MapPartitionsRDD[234] at mapPartitions at PythonMLLibAPI.scala:1493
INFO:[13/Jun/2016:19:33:01] ENGINE Keyboard Interrupt: shutting down bus
INFO:[13/Jun/2016:19:33:01] ENGINE Bus STOPPING
INFO:[13/Jun/2016:19:33:01] ENGINE HTTP Server cherrypy._cpwsgi_server.CPWSGIServer(('0.0.0.0', 5432)) shut down
INFO:[13/Jun/2016:19:33:01] ENGINE Stopped thread 'Autoreloader'.
INFO:[13/Jun/2016:19:33:01] ENGINE Stopped thread '_TimeoutMonitor'.
INFO:[13/Jun/2016:19:33:01] ENGINE Bus STOPPED
INFO:[13/Jun/2016:19:33:01] ENGINE Bus EXITING
INFO:[13/Jun/2016:19:33:01] ENGINE Bus EXITED
INFO:[13/Jun/2016:19:33:01] ENGINE Waiting for child threads to terminate...
INFO:Calentando motores...
INFO:[13/Jun/2016:19:37:45] ENGINE Bus STARTING
INFO:[13/Jun/2016:19:37:45] ENGINE Started monitor thread '_TimeoutMonitor'.
INFO:[13/Jun/2016:19:37:45] ENGINE Started monitor thread 'Autoreloader'.
INFO:[13/Jun/2016:19:37:45] ENGINE Serving on http://0.0.0.0:5432
INFO:[13/Jun/2016:19:37:45] ENGINE Bus STARTED
INFO:Cargando arhcivos...
INFO:Calculando features para tweets...
INFO:Iniciando calculo de tweets por dia...
INFO:Iniciando calculo de tweets por hora...
INFO:Iniciando exploracion de las fuentes de los tweets...
INFO:Iniciando calculo de diversidad lexicografica...
INFO:Iniciando calculo del promedio de la longuitud de los tweets...
INFO:Iniciando calculo del ratio de respuestas...
INFO:Iniciando calculo del promedio de los hashtags...
INFO:Iniciando calculo del promedio de menciones...
INFO:Iniciando calculo del promedio de palabras por tweet...
INFO:Iniciando calculo del promedio de diversidad de palabras...
INFO:Iniciando calculo del ratio de urls...
INFO:Registrando tablas...
INFO:Join entre tweets...
INFO:Calculando features para usuarios...
INFO:Realizando join de usuarios con tweets...
INFO:Finalizado el join...
ERROR:Exception on /evaluar/ [POST]
Traceback (most recent call last):
  File "/usr/local/lib/python2.7/dist-packages/flask/app.py", line 1817, in wsgi_app
    response = self.full_dispatch_request()
  File "/usr/local/lib/python2.7/dist-packages/flask/app.py", line 1477, in full_dispatch_request
    rv = self.handle_user_exception(e)
  File "/usr/local/lib/python2.7/dist-packages/flask/app.py", line 1381, in handle_user_exception
    reraise(exc_type, exc_value, tb)
  File "/usr/local/lib/python2.7/dist-packages/flask/app.py", line 1475, in full_dispatch_request
    rv = self.dispatch_request()
  File "/usr/local/lib/python2.7/dist-packages/flask/app.py", line 1461, in dispatch_request
    return self.view_functions[rule.endpoint](**req.view_args)
  File "/home/jduarte/Workspace/TesisSpark/app.py", line 33, in evaluar
    resultado = motor_clasificador.evaluar(directorio)
  File "/home/jduarte/Workspace/TesisSpark/engine.py", line 184, in evaluar
    resultado = modelo.predict(features).collect()
  File "/home/jduarte/Herramientas/spark/python/lib/pyspark.zip/pyspark/rdd.py", line 771, in collect
    port = self.ctx._jvm.PythonRDD.collectAndServe(self._jrdd.rdd())
  File "/home/jduarte/Herramientas/spark/python/lib/py4j-0.9-src.zip/py4j/java_gateway.py", line 813, in __call__
    answer, self.gateway_client, self.target_id, self.name)
  File "/home/jduarte/Herramientas/spark/python/lib/pyspark.zip/pyspark/sql/utils.py", line 45, in deco
    return f(*a, **kw)
  File "/home/jduarte/Herramientas/spark/python/lib/py4j-0.9-src.zip/py4j/protocol.py", line 308, in get_return_value
    format(target_id, ".", name), value)
Py4JJavaError: An error occurred while calling z:org.apache.spark.api.python.PythonRDD.collectAndServe.
: org.apache.spark.SparkException: Job aborted due to stage failure: Task 180 in stage 84.0 failed 1 times, most recent failure: Lost task 180.0 in stage 84.0 (TID 272, localhost): org.apache.spark.api.python.PythonException: Traceback (most recent call last):
  File "/home/jduarte/Herramientas/spark/python/lib/pyspark.zip/pyspark/worker.py", line 111, in main
    process()
  File "/home/jduarte/Herramientas/spark/python/lib/pyspark.zip/pyspark/worker.py", line 106, in process
    serializer.dump_stream(func(split_index, iterator), outfile)
  File "/home/jduarte/Herramientas/spark/python/lib/pyspark.zip/pyspark/serializers.py", line 263, in dump_stream
    vs = list(itertools.islice(iterator, batch))
  File "/home/jduarte/Herramientas/spark/python/lib/pyspark.zip/pyspark/mllib/linalg/__init__.py", line 71, in _convert_to_vector
    return DenseVector(l)
  File "/home/jduarte/Herramientas/spark/python/lib/pyspark.zip/pyspark/mllib/linalg/__init__.py", line 274, in __init__
    ar = np.array(ar, dtype=np.float64)
ValueError: setting an array element with a sequence.

	at org.apache.spark.api.python.PythonRunner$$anon$1.read(PythonRDD.scala:166)
	at org.apache.spark.api.python.PythonRunner$$anon$1.<init>(PythonRDD.scala:207)
	at org.apache.spark.api.python.PythonRunner.compute(PythonRDD.scala:125)
	at org.apache.spark.api.python.PythonRDD.compute(PythonRDD.scala:70)
	at org.apache.spark.rdd.RDD.computeOrReadCheckpoint(RDD.scala:306)
	at org.apache.spark.rdd.RDD.iterator(RDD.scala:270)
	at org.apache.spark.rdd.MapPartitionsRDD.compute(MapPartitionsRDD.scala:38)
	at org.apache.spark.rdd.RDD.computeOrReadCheckpoint(RDD.scala:306)
	at org.apache.spark.rdd.RDD.iterator(RDD.scala:270)
	at org.apache.spark.rdd.MapPartitionsRDD.compute(MapPartitionsRDD.scala:38)
	at org.apache.spark.rdd.RDD.computeOrReadCheckpoint(RDD.scala:306)
	at org.apache.spark.rdd.RDD.iterator(RDD.scala:270)
	at org.apache.spark.rdd.MapPartitionsRDD.compute(MapPartitionsRDD.scala:38)
	at org.apache.spark.rdd.RDD.computeOrReadCheckpoint(RDD.scala:306)
	at org.apache.spark.rdd.RDD.iterator(RDD.scala:270)
	at org.apache.spark.scheduler.ResultTask.runTask(ResultTask.scala:66)
	at org.apache.spark.scheduler.Task.run(Task.scala:89)
	at org.apache.spark.executor.Executor$TaskRunner.run(Executor.scala:214)
	at java.util.concurrent.ThreadPoolExecutor.runWorker(ThreadPoolExecutor.java:1142)
	at java.util.concurrent.ThreadPoolExecutor$Worker.run(ThreadPoolExecutor.java:617)
	at java.lang.Thread.run(Thread.java:745)

Driver stacktrace:
	at org.apache.spark.scheduler.DAGScheduler.org$apache$spark$scheduler$DAGScheduler$$failJobAndIndependentStages(DAGScheduler.scala:1431)
	at org.apache.spark.scheduler.DAGScheduler$$anonfun$abortStage$1.apply(DAGScheduler.scala:1419)
	at org.apache.spark.scheduler.DAGScheduler$$anonfun$abortStage$1.apply(DAGScheduler.scala:1418)
	at scala.collection.mutable.ResizableArray$class.foreach(ResizableArray.scala:59)
	at scala.collection.mutable.ArrayBuffer.foreach(ArrayBuffer.scala:47)
	at org.apache.spark.scheduler.DAGScheduler.abortStage(DAGScheduler.scala:1418)
	at org.apache.spark.scheduler.DAGScheduler$$anonfun$handleTaskSetFailed$1.apply(DAGScheduler.scala:799)
	at org.apache.spark.scheduler.DAGScheduler$$anonfun$handleTaskSetFailed$1.apply(DAGScheduler.scala:799)
	at scala.Option.foreach(Option.scala:236)
	at org.apache.spark.scheduler.DAGScheduler.handleTaskSetFailed(DAGScheduler.scala:799)
	at org.apache.spark.scheduler.DAGSchedulerEventProcessLoop.doOnReceive(DAGScheduler.scala:1640)
	at org.apache.spark.scheduler.DAGSchedulerEventProcessLoop.onReceive(DAGScheduler.scala:1599)
	at org.apache.spark.scheduler.DAGSchedulerEventProcessLoop.onReceive(DAGScheduler.scala:1588)
	at org.apache.spark.util.EventLoop$$anon$1.run(EventLoop.scala:48)
	at org.apache.spark.scheduler.DAGScheduler.runJob(DAGScheduler.scala:620)
	at org.apache.spark.SparkContext.runJob(SparkContext.scala:1832)
	at org.apache.spark.SparkContext.runJob(SparkContext.scala:1845)
	at org.apache.spark.SparkContext.runJob(SparkContext.scala:1858)
	at org.apache.spark.SparkContext.runJob(SparkContext.scala:1929)
	at org.apache.spark.rdd.RDD$$anonfun$collect$1.apply(RDD.scala:927)
	at org.apache.spark.rdd.RDDOperationScope$.withScope(RDDOperationScope.scala:150)
	at org.apache.spark.rdd.RDDOperationScope$.withScope(RDDOperationScope.scala:111)
	at org.apache.spark.rdd.RDD.withScope(RDD.scala:316)
	at org.apache.spark.rdd.RDD.collect(RDD.scala:926)
	at org.apache.spark.api.python.PythonRDD$.collectAndServe(PythonRDD.scala:405)
	at org.apache.spark.api.python.PythonRDD.collectAndServe(PythonRDD.scala)
	at sun.reflect.NativeMethodAccessorImpl.invoke0(Native Method)
	at sun.reflect.NativeMethodAccessorImpl.invoke(NativeMethodAccessorImpl.java:62)
	at sun.reflect.DelegatingMethodAccessorImpl.invoke(DelegatingMethodAccessorImpl.java:43)
	at java.lang.reflect.Method.invoke(Method.java:498)
	at py4j.reflection.MethodInvoker.invoke(MethodInvoker.java:231)
	at py4j.reflection.ReflectionEngine.invoke(ReflectionEngine.java:381)
	at py4j.Gateway.invoke(Gateway.java:259)
	at py4j.commands.AbstractCommand.invokeMethod(AbstractCommand.java:133)
	at py4j.commands.CallCommand.execute(CallCommand.java:79)
	at py4j.GatewayConnection.run(GatewayConnection.java:209)
	at java.lang.Thread.run(Thread.java:745)
Caused by: org.apache.spark.api.python.PythonException: Traceback (most recent call last):
  File "/home/jduarte/Herramientas/spark/python/lib/pyspark.zip/pyspark/worker.py", line 111, in main
    process()
  File "/home/jduarte/Herramientas/spark/python/lib/pyspark.zip/pyspark/worker.py", line 106, in process
    serializer.dump_stream(func(split_index, iterator), outfile)
  File "/home/jduarte/Herramientas/spark/python/lib/pyspark.zip/pyspark/serializers.py", line 263, in dump_stream
    vs = list(itertools.islice(iterator, batch))
  File "/home/jduarte/Herramientas/spark/python/lib/pyspark.zip/pyspark/mllib/linalg/__init__.py", line 71, in _convert_to_vector
    return DenseVector(l)
  File "/home/jduarte/Herramientas/spark/python/lib/pyspark.zip/pyspark/mllib/linalg/__init__.py", line 274, in __init__
    ar = np.array(ar, dtype=np.float64)
ValueError: setting an array element with a sequence.

	at org.apache.spark.api.python.PythonRunner$$anon$1.read(PythonRDD.scala:166)
	at org.apache.spark.api.python.PythonRunner$$anon$1.<init>(PythonRDD.scala:207)
	at org.apache.spark.api.python.PythonRunner.compute(PythonRDD.scala:125)
	at org.apache.spark.api.python.PythonRDD.compute(PythonRDD.scala:70)
	at org.apache.spark.rdd.RDD.computeOrReadCheckpoint(RDD.scala:306)
	at org.apache.spark.rdd.RDD.iterator(RDD.scala:270)
	at org.apache.spark.rdd.MapPartitionsRDD.compute(MapPartitionsRDD.scala:38)
	at org.apache.spark.rdd.RDD.computeOrReadCheckpoint(RDD.scala:306)
	at org.apache.spark.rdd.RDD.iterator(RDD.scala:270)
	at org.apache.spark.rdd.MapPartitionsRDD.compute(MapPartitionsRDD.scala:38)
	at org.apache.spark.rdd.RDD.computeOrReadCheckpoint(RDD.scala:306)
	at org.apache.spark.rdd.RDD.iterator(RDD.scala:270)
	at org.apache.spark.rdd.MapPartitionsRDD.compute(MapPartitionsRDD.scala:38)
	at org.apache.spark.rdd.RDD.computeOrReadCheckpoint(RDD.scala:306)
	at org.apache.spark.rdd.RDD.iterator(RDD.scala:270)
	at org.apache.spark.scheduler.ResultTask.runTask(ResultTask.scala:66)
	at org.apache.spark.scheduler.Task.run(Task.scala:89)
	at org.apache.spark.executor.Executor$TaskRunner.run(Executor.scala:214)
	at java.util.concurrent.ThreadPoolExecutor.runWorker(ThreadPoolExecutor.java:1142)
	at java.util.concurrent.ThreadPoolExecutor$Worker.run(ThreadPoolExecutor.java:617)
	... 1 more

INFO:[13/Jun/2016:19:40:23] ENGINE Restarting because /home/jduarte/Workspace/TesisSpark/tools.py changed.
INFO:[13/Jun/2016:19:40:23] ENGINE Stopped thread 'Autoreloader'.
INFO:[13/Jun/2016:19:40:23] ENGINE Bus STOPPING
INFO:[13/Jun/2016:19:40:23] ENGINE HTTP Server cherrypy._cpwsgi_server.CPWSGIServer(('0.0.0.0', 5432)) shut down
INFO:[13/Jun/2016:19:40:23] ENGINE Stopped thread '_TimeoutMonitor'.
INFO:[13/Jun/2016:19:40:23] ENGINE Bus STOPPED
INFO:[13/Jun/2016:19:40:23] ENGINE Bus EXITING
INFO:[13/Jun/2016:19:40:23] ENGINE Bus EXITED
INFO:[13/Jun/2016:19:40:24] ENGINE Waiting for child threads to terminate...
INFO:[13/Jun/2016:19:40:24] ENGINE Re-spawning /home/jduarte/Workspace/TesisSpark/server.py
INFO:Calentando motores...
INFO:[13/Jun/2016:19:40:34] ENGINE Bus STARTING
INFO:[13/Jun/2016:19:40:34] ENGINE Started monitor thread '_TimeoutMonitor'.
INFO:[13/Jun/2016:19:40:34] ENGINE Started monitor thread 'Autoreloader'.
INFO:[13/Jun/2016:19:40:34] ENGINE Serving on http://0.0.0.0:5432
INFO:[13/Jun/2016:19:40:34] ENGINE Bus STARTED
INFO:Cargando arhcivos...
INFO:Calculando features para tweets...
INFO:Iniciando calculo de tweets por dia...
INFO:Iniciando calculo de tweets por hora...
INFO:Iniciando exploracion de las fuentes de los tweets...
INFO:Iniciando calculo de diversidad lexicografica...
INFO:Iniciando calculo del promedio de la longuitud de los tweets...
INFO:Iniciando calculo del ratio de respuestas...
INFO:Iniciando calculo del promedio de los hashtags...
INFO:Iniciando calculo del promedio de menciones...
INFO:Iniciando calculo del promedio de palabras por tweet...
INFO:Iniciando calculo del promedio de diversidad de palabras...
INFO:Iniciando calculo del ratio de urls...
INFO:Registrando tablas...
INFO:Join entre tweets...
INFO:Calculando features para usuarios...
INFO:Realizando join de usuarios con tweets...
INFO:Finalizado el join...
INFO:[0.99]
INFO:[13/Jun/2016:19:42:42] ENGINE Restarting because /home/jduarte/Workspace/TesisSpark/tools.py changed.
INFO:[13/Jun/2016:19:42:42] ENGINE Stopped thread 'Autoreloader'.
INFO:[13/Jun/2016:19:42:42] ENGINE Bus STOPPING
INFO:[13/Jun/2016:19:42:42] ENGINE HTTP Server cherrypy._cpwsgi_server.CPWSGIServer(('0.0.0.0', 5432)) shut down
INFO:[13/Jun/2016:19:42:42] ENGINE Stopped thread '_TimeoutMonitor'.
INFO:[13/Jun/2016:19:42:42] ENGINE Bus STOPPED
INFO:[13/Jun/2016:19:42:42] ENGINE Bus EXITING
INFO:[13/Jun/2016:19:42:42] ENGINE Bus EXITED
INFO:[13/Jun/2016:19:42:42] ENGINE Waiting for child threads to terminate...
INFO:[13/Jun/2016:19:42:42] ENGINE Re-spawning /home/jduarte/Workspace/TesisSpark/server.py
INFO:Calentando motores...
INFO:[13/Jun/2016:19:43:01] ENGINE Bus STARTING
INFO:[13/Jun/2016:19:43:01] ENGINE Started monitor thread '_TimeoutMonitor'.
INFO:[13/Jun/2016:19:43:01] ENGINE Started monitor thread 'Autoreloader'.
INFO:[13/Jun/2016:19:43:01] ENGINE Serving on http://0.0.0.0:5432
INFO:[13/Jun/2016:19:43:01] ENGINE Bus STARTED
INFO:Cargando arhcivos...
INFO:Calculando features para tweets...
INFO:Iniciando calculo de tweets por dia...
INFO:Iniciando calculo de tweets por hora...
INFO:Iniciando exploracion de las fuentes de los tweets...
INFO:Iniciando calculo de diversidad lexicografica...
INFO:Iniciando calculo del promedio de la longuitud de los tweets...
INFO:Iniciando calculo del ratio de respuestas...
INFO:Iniciando calculo del promedio de los hashtags...
INFO:Iniciando calculo del promedio de menciones...
INFO:Iniciando calculo del promedio de palabras por tweet...
INFO:Iniciando calculo del promedio de diversidad de palabras...
INFO:Iniciando calculo del ratio de urls...
INFO:Registrando tablas...
INFO:Join entre tweets...
INFO:Calculando features para usuarios...
INFO:Realizando join de usuarios con tweets...
INFO:Finalizado el join...
INFO:MapPartitionsRDD[234] at mapPartitions at PythonMLLibAPI.scala:1493
INFO:[13/Jun/2016:19:44:57] ENGINE Keyboard Interrupt: shutting down bus
INFO:[13/Jun/2016:19:44:57] ENGINE Bus STOPPING
INFO:[13/Jun/2016:19:44:57] ENGINE HTTP Server cherrypy._cpwsgi_server.CPWSGIServer(('0.0.0.0', 5432)) shut down
INFO:[13/Jun/2016:19:44:57] ENGINE Stopped thread 'Autoreloader'.
INFO:[13/Jun/2016:19:44:57] ENGINE Stopped thread '_TimeoutMonitor'.
INFO:[13/Jun/2016:19:44:57] ENGINE Bus STOPPED
INFO:[13/Jun/2016:19:44:57] ENGINE Bus EXITING
INFO:[13/Jun/2016:19:44:57] ENGINE Bus EXITED
INFO:[13/Jun/2016:19:44:57] ENGINE Waiting for child threads to terminate...
INFO:Calentando motores...
INFO:[13/Jun/2016:19:50:01] ENGINE Bus STARTING
INFO:[13/Jun/2016:19:50:01] ENGINE Started monitor thread '_TimeoutMonitor'.
INFO:[13/Jun/2016:19:50:01] ENGINE Started monitor thread 'Autoreloader'.
INFO:[13/Jun/2016:19:50:01] ENGINE Serving on http://0.0.0.0:5432
INFO:[13/Jun/2016:19:50:01] ENGINE Bus STARTED
INFO:{u'humano': u'/home/jduarte/Workspace/datos/datos_cat/humano', u'ciborg': u'/home/jduarte/Workspace/datos/datos_cat/ciborg', u'bot': u'/home/jduarte/Workspace/datos/datos_cat/bot'}
INFO:Cargando timelines...
INFO:Calculo de features en tweetsRDD_humanos...
INFO:Calculando features para tweets...
INFO:Iniciando calculo de tweets por dia...
INFO:Iniciando calculo de tweets por hora...
INFO:Iniciando exploracion de las fuentes de los tweets...
INFO:Iniciando calculo de diversidad lexicografica...
INFO:Iniciando calculo del promedio de la longuitud de los tweets...
INFO:Iniciando calculo del ratio de respuestas...
INFO:Iniciando calculo del promedio de los hashtags...
INFO:Iniciando calculo del promedio de menciones...
INFO:Iniciando calculo del promedio de palabras por tweet...
INFO:Iniciando calculo del promedio de diversidad de palabras...
INFO:Iniciando calculo del ratio de urls...
INFO:Registrando tablas...
INFO:Join entre tweets...
INFO:Calculo de features en tweetsRDD_bots...
INFO:Calculando features para tweets...
INFO:Iniciando calculo de tweets por dia...
INFO:Iniciando calculo de tweets por hora...
INFO:Iniciando exploracion de las fuentes de los tweets...
INFO:Iniciando calculo de diversidad lexicografica...
INFO:Iniciando calculo del promedio de la longuitud de los tweets...
INFO:Iniciando calculo del ratio de respuestas...
INFO:Iniciando calculo del promedio de los hashtags...
INFO:Iniciando calculo del promedio de menciones...
INFO:Iniciando calculo del promedio de palabras por tweet...
INFO:Iniciando calculo del promedio de diversidad de palabras...
INFO:Iniciando calculo del ratio de urls...
INFO:Registrando tablas...
INFO:Join entre tweets...
INFO:Calculo de features en tweetsRDD_ciborgs...
INFO:Calculando features para tweets...
INFO:Iniciando calculo de tweets por dia...
INFO:Iniciando calculo de tweets por hora...
INFO:Iniciando exploracion de las fuentes de los tweets...
INFO:Iniciando calculo de diversidad lexicografica...
INFO:Iniciando calculo del promedio de la longuitud de los tweets...
INFO:Iniciando calculo del ratio de respuestas...
INFO:Iniciando calculo del promedio de los hashtags...
INFO:Iniciando calculo del promedio de menciones...
INFO:Iniciando calculo del promedio de palabras por tweet...
INFO:Iniciando calculo del promedio de diversidad de palabras...
INFO:Iniciando calculo del ratio de urls...
INFO:Registrando tablas...
INFO:Join entre tweets...
INFO:Calculo de features en usuariosRDD_humanos...
INFO:Calculando features para usuarios...
INFO:Calculo de features en usuariosRDD_bots...
INFO:Calculando features para usuarios...
INFO:Calculo de features en usuariosRDD_ciborgs...
INFO:Calculando features para usuarios...
INFO:Realizando Union...
INFO:Realizando Join...
INFO:Guardando modelo...
INFO:Finalizando...
INFO:Cargando arhcivos...
INFO:Calculando features para tweets...
INFO:Iniciando calculo de tweets por dia...
INFO:Iniciando calculo de tweets por hora...
INFO:Iniciando exploracion de las fuentes de los tweets...
INFO:Iniciando calculo de diversidad lexicografica...
INFO:Iniciando calculo del promedio de la longuitud de los tweets...
INFO:Iniciando calculo del ratio de respuestas...
INFO:Iniciando calculo del promedio de los hashtags...
INFO:Iniciando calculo del promedio de menciones...
INFO:Iniciando calculo del promedio de palabras por tweet...
INFO:Iniciando calculo del promedio de diversidad de palabras...
INFO:Iniciando calculo del ratio de urls...
INFO:Registrando tablas...
INFO:Join entre tweets...
INFO:Calculando features para usuarios...
INFO:Realizando join de usuarios con tweets...
INFO:Finalizado el join...
INFO:MapPartitionsRDD[918] at mapPartitions at PythonMLLibAPI.scala:1493
INFO:[13/Jun/2016:19:56:17] ENGINE Keyboard Interrupt: shutting down bus
INFO:[13/Jun/2016:19:56:17] ENGINE Bus STOPPING
INFO:[13/Jun/2016:19:56:18] ENGINE HTTP Server cherrypy._cpwsgi_server.CPWSGIServer(('0.0.0.0', 5432)) shut down
INFO:[13/Jun/2016:19:56:18] ENGINE Stopped thread 'Autoreloader'.
INFO:[13/Jun/2016:19:56:18] ENGINE Stopped thread '_TimeoutMonitor'.
INFO:[13/Jun/2016:19:56:18] ENGINE Bus STOPPED
INFO:[13/Jun/2016:19:56:18] ENGINE Bus EXITING
INFO:[13/Jun/2016:19:56:18] ENGINE Bus EXITED
INFO:[13/Jun/2016:19:56:18] ENGINE Waiting for child threads to terminate...
ERROR:Error while sending or receiving.
Traceback (most recent call last):
  File "/home/jduarte/Herramientas/spark/python/lib/py4j-0.9-src.zip/py4j/java_gateway.py", line 746, in send_command
    raise Py4JError("Answer from Java side is empty")
Py4JError: Answer from Java side is empty
INFO:Exception while sending command.
Traceback (most recent call last):
  File "/home/jduarte/Herramientas/spark/python/lib/py4j-0.9-src.zip/py4j/java_gateway.py", line 626, in send_command
    response = connection.send_command(command)
  File "/home/jduarte/Herramientas/spark/python/lib/py4j-0.9-src.zip/py4j/java_gateway.py", line 750, in send_command
    raise Py4JNetworkError("Error while sending or receiving", e)
Py4JNetworkError: Error while sending or receiving
ERROR:Error while sending or receiving.
Traceback (most recent call last):
  File "/home/jduarte/Herramientas/spark/python/lib/py4j-0.9-src.zip/py4j/java_gateway.py", line 746, in send_command
    raise Py4JError("Answer from Java side is empty")
Py4JError: Answer from Java side is empty
INFO:Exception while sending command.
Traceback (most recent call last):
  File "/home/jduarte/Herramientas/spark/python/lib/py4j-0.9-src.zip/py4j/java_gateway.py", line 626, in send_command
    response = connection.send_command(command)
  File "/home/jduarte/Herramientas/spark/python/lib/py4j-0.9-src.zip/py4j/java_gateway.py", line 750, in send_command
    raise Py4JNetworkError("Error while sending or receiving", e)
Py4JNetworkError: Error while sending or receiving
ERROR:An error occurred while trying to connect to the Java server
Traceback (most recent call last):
  File "/home/jduarte/Herramientas/spark/python/lib/py4j-0.9-src.zip/py4j/java_gateway.py", line 690, in start
    self.socket.connect((self.address, self.port))
  File "/usr/lib/python2.7/socket.py", line 224, in meth
    return getattr(self._sock,name)(*args)
error: [Errno 111] Connection refused
ERROR:An error occurred while trying to connect to the Java server
Traceback (most recent call last):
  File "/home/jduarte/Herramientas/spark/python/lib/py4j-0.9-src.zip/py4j/java_gateway.py", line 690, in start
    self.socket.connect((self.address, self.port))
  File "/usr/lib/python2.7/socket.py", line 224, in meth
    return getattr(self._sock,name)(*args)
error: [Errno 111] Connection refused
ERROR:An error occurred while trying to connect to the Java server
Traceback (most recent call last):
  File "/home/jduarte/Herramientas/spark/python/lib/py4j-0.9-src.zip/py4j/java_gateway.py", line 690, in start
    self.socket.connect((self.address, self.port))
  File "/usr/lib/python2.7/socket.py", line 224, in meth
    return getattr(self._sock,name)(*args)
error: [Errno 111] Connection refused
ERROR:An error occurred while trying to connect to the Java server
Traceback (most recent call last):
  File "/home/jduarte/Herramientas/spark/python/lib/py4j-0.9-src.zip/py4j/java_gateway.py", line 690, in start
    self.socket.connect((self.address, self.port))
  File "/usr/lib/python2.7/socket.py", line 224, in meth
    return getattr(self._sock,name)(*args)
error: [Errno 111] Connection refused
ERROR:An error occurred while trying to connect to the Java server
Traceback (most recent call last):
  File "/home/jduarte/Herramientas/spark/python/lib/py4j-0.9-src.zip/py4j/java_gateway.py", line 690, in start
    self.socket.connect((self.address, self.port))
  File "/usr/lib/python2.7/socket.py", line 224, in meth
    return getattr(self._sock,name)(*args)
error: [Errno 111] Connection refused
ERROR:An error occurred while trying to connect to the Java server
Traceback (most recent call last):
  File "/home/jduarte/Herramientas/spark/python/lib/py4j-0.9-src.zip/py4j/java_gateway.py", line 690, in start
    self.socket.connect((self.address, self.port))
  File "/usr/lib/python2.7/socket.py", line 224, in meth
    return getattr(self._sock,name)(*args)
error: [Errno 111] Connection refused
ERROR:An error occurred while trying to connect to the Java server
Traceback (most recent call last):
  File "/home/jduarte/Herramientas/spark/python/lib/py4j-0.9-src.zip/py4j/java_gateway.py", line 690, in start
    self.socket.connect((self.address, self.port))
  File "/usr/lib/python2.7/socket.py", line 224, in meth
    return getattr(self._sock,name)(*args)
error: [Errno 111] Connection refused
ERROR:An error occurred while trying to connect to the Java server
Traceback (most recent call last):
  File "/home/jduarte/Herramientas/spark/python/lib/py4j-0.9-src.zip/py4j/java_gateway.py", line 690, in start
    self.socket.connect((self.address, self.port))
  File "/usr/lib/python2.7/socket.py", line 224, in meth
    return getattr(self._sock,name)(*args)
error: [Errno 111] Connection refused
ERROR:An error occurred while trying to connect to the Java server
Traceback (most recent call last):
  File "/home/jduarte/Herramientas/spark/python/lib/py4j-0.9-src.zip/py4j/java_gateway.py", line 690, in start
    self.socket.connect((self.address, self.port))
  File "/usr/lib/python2.7/socket.py", line 224, in meth
    return getattr(self._sock,name)(*args)
error: [Errno 111] Connection refused
ERROR:An error occurred while trying to connect to the Java server
Traceback (most recent call last):
  File "/home/jduarte/Herramientas/spark/python/lib/py4j-0.9-src.zip/py4j/java_gateway.py", line 690, in start
    self.socket.connect((self.address, self.port))
  File "/usr/lib/python2.7/socket.py", line 224, in meth
    return getattr(self._sock,name)(*args)
error: [Errno 111] Connection refused
ERROR:An error occurred while trying to connect to the Java server
Traceback (most recent call last):
  File "/home/jduarte/Herramientas/spark/python/lib/py4j-0.9-src.zip/py4j/java_gateway.py", line 690, in start
    self.socket.connect((self.address, self.port))
  File "/usr/lib/python2.7/socket.py", line 224, in meth
    return getattr(self._sock,name)(*args)
error: [Errno 111] Connection refused
ERROR:An error occurred while trying to connect to the Java server
Traceback (most recent call last):
  File "/home/jduarte/Herramientas/spark/python/lib/py4j-0.9-src.zip/py4j/java_gateway.py", line 690, in start
    self.socket.connect((self.address, self.port))
  File "/usr/lib/python2.7/socket.py", line 224, in meth
    return getattr(self._sock,name)(*args)
error: [Errno 111] Connection refused
ERROR:An error occurred while trying to connect to the Java server
Traceback (most recent call last):
  File "/home/jduarte/Herramientas/spark/python/lib/py4j-0.9-src.zip/py4j/java_gateway.py", line 690, in start
    self.socket.connect((self.address, self.port))
  File "/usr/lib/python2.7/socket.py", line 224, in meth
    return getattr(self._sock,name)(*args)
error: [Errno 111] Connection refused
ERROR:An error occurred while trying to connect to the Java server
Traceback (most recent call last):
  File "/home/jduarte/Herramientas/spark/python/lib/py4j-0.9-src.zip/py4j/java_gateway.py", line 690, in start
    self.socket.connect((self.address, self.port))
  File "/usr/lib/python2.7/socket.py", line 224, in meth
    return getattr(self._sock,name)(*args)
error: [Errno 111] Connection refused
ERROR:An error occurred while trying to connect to the Java server
Traceback (most recent call last):
  File "/home/jduarte/Herramientas/spark/python/lib/py4j-0.9-src.zip/py4j/java_gateway.py", line 690, in start
    self.socket.connect((self.address, self.port))
  File "/usr/lib/python2.7/socket.py", line 224, in meth
    return getattr(self._sock,name)(*args)
error: [Errno 111] Connection refused
ERROR:An error occurred while trying to connect to the Java server
Traceback (most recent call last):
  File "/home/jduarte/Herramientas/spark/python/lib/py4j-0.9-src.zip/py4j/java_gateway.py", line 690, in start
    self.socket.connect((self.address, self.port))
  File "/usr/lib/python2.7/socket.py", line 224, in meth
    return getattr(self._sock,name)(*args)
error: [Errno 111] Connection refused
ERROR:An error occurred while trying to connect to the Java server
Traceback (most recent call last):
  File "/home/jduarte/Herramientas/spark/python/lib/py4j-0.9-src.zip/py4j/java_gateway.py", line 690, in start
    self.socket.connect((self.address, self.port))
  File "/usr/lib/python2.7/socket.py", line 224, in meth
    return getattr(self._sock,name)(*args)
error: [Errno 111] Connection refused
ERROR:An error occurred while trying to connect to the Java server
Traceback (most recent call last):
  File "/home/jduarte/Herramientas/spark/python/lib/py4j-0.9-src.zip/py4j/java_gateway.py", line 690, in start
    self.socket.connect((self.address, self.port))
  File "/usr/lib/python2.7/socket.py", line 224, in meth
    return getattr(self._sock,name)(*args)
error: [Errno 111] Connection refused
ERROR:An error occurred while trying to connect to the Java server
Traceback (most recent call last):
  File "/home/jduarte/Herramientas/spark/python/lib/py4j-0.9-src.zip/py4j/java_gateway.py", line 690, in start
    self.socket.connect((self.address, self.port))
  File "/usr/lib/python2.7/socket.py", line 224, in meth
    return getattr(self._sock,name)(*args)
error: [Errno 111] Connection refused
ERROR:An error occurred while trying to connect to the Java server
Traceback (most recent call last):
  File "/home/jduarte/Herramientas/spark/python/lib/py4j-0.9-src.zip/py4j/java_gateway.py", line 690, in start
    self.socket.connect((self.address, self.port))
  File "/usr/lib/python2.7/socket.py", line 224, in meth
    return getattr(self._sock,name)(*args)
error: [Errno 111] Connection refused
ERROR:An error occurred while trying to connect to the Java server
Traceback (most recent call last):
  File "/home/jduarte/Herramientas/spark/python/lib/py4j-0.9-src.zip/py4j/java_gateway.py", line 690, in start
    self.socket.connect((self.address, self.port))
  File "/usr/lib/python2.7/socket.py", line 224, in meth
    return getattr(self._sock,name)(*args)
error: [Errno 111] Connection refused
ERROR:An error occurred while trying to connect to the Java server
Traceback (most recent call last):
  File "/home/jduarte/Herramientas/spark/python/lib/py4j-0.9-src.zip/py4j/java_gateway.py", line 690, in start
    self.socket.connect((self.address, self.port))
  File "/usr/lib/python2.7/socket.py", line 224, in meth
    return getattr(self._sock,name)(*args)
error: [Errno 111] Connection refused
ERROR:An error occurred while trying to connect to the Java server
Traceback (most recent call last):
  File "/home/jduarte/Herramientas/spark/python/lib/py4j-0.9-src.zip/py4j/java_gateway.py", line 690, in start
    self.socket.connect((self.address, self.port))
  File "/usr/lib/python2.7/socket.py", line 224, in meth
    return getattr(self._sock,name)(*args)
error: [Errno 111] Connection refused
ERROR:An error occurred while trying to connect to the Java server
Traceback (most recent call last):
  File "/home/jduarte/Herramientas/spark/python/lib/py4j-0.9-src.zip/py4j/java_gateway.py", line 690, in start
    self.socket.connect((self.address, self.port))
  File "/usr/lib/python2.7/socket.py", line 224, in meth
    return getattr(self._sock,name)(*args)
error: [Errno 111] Connection refused
ERROR:An error occurred while trying to connect to the Java server
Traceback (most recent call last):
  File "/home/jduarte/Herramientas/spark/python/lib/py4j-0.9-src.zip/py4j/java_gateway.py", line 690, in start
    self.socket.connect((self.address, self.port))
  File "/usr/lib/python2.7/socket.py", line 224, in meth
    return getattr(self._sock,name)(*args)
error: [Errno 111] Connection refused
ERROR:An error occurred while trying to connect to the Java server
Traceback (most recent call last):
  File "/home/jduarte/Herramientas/spark/python/lib/py4j-0.9-src.zip/py4j/java_gateway.py", line 690, in start
    self.socket.connect((self.address, self.port))
  File "/usr/lib/python2.7/socket.py", line 224, in meth
    return getattr(self._sock,name)(*args)
error: [Errno 111] Connection refused
ERROR:An error occurred while trying to connect to the Java server
Traceback (most recent call last):
  File "/home/jduarte/Herramientas/spark/python/lib/py4j-0.9-src.zip/py4j/java_gateway.py", line 690, in start
    self.socket.connect((self.address, self.port))
  File "/usr/lib/python2.7/socket.py", line 224, in meth
    return getattr(self._sock,name)(*args)
error: [Errno 111] Connection refused
ERROR:An error occurred while trying to connect to the Java server
Traceback (most recent call last):
  File "/home/jduarte/Herramientas/spark/python/lib/py4j-0.9-src.zip/py4j/java_gateway.py", line 690, in start
    self.socket.connect((self.address, self.port))
  File "/usr/lib/python2.7/socket.py", line 224, in meth
    return getattr(self._sock,name)(*args)
error: [Errno 111] Connection refused
ERROR:An error occurred while trying to connect to the Java server
Traceback (most recent call last):
  File "/home/jduarte/Herramientas/spark/python/lib/py4j-0.9-src.zip/py4j/java_gateway.py", line 690, in start
    self.socket.connect((self.address, self.port))
  File "/usr/lib/python2.7/socket.py", line 224, in meth
    return getattr(self._sock,name)(*args)
error: [Errno 111] Connection refused
ERROR:An error occurred while trying to connect to the Java server
Traceback (most recent call last):
  File "/home/jduarte/Herramientas/spark/python/lib/py4j-0.9-src.zip/py4j/java_gateway.py", line 690, in start
    self.socket.connect((self.address, self.port))
  File "/usr/lib/python2.7/socket.py", line 224, in meth
    return getattr(self._sock,name)(*args)
error: [Errno 111] Connection refused
ERROR:An error occurred while trying to connect to the Java server
Traceback (most recent call last):
  File "/home/jduarte/Herramientas/spark/python/lib/py4j-0.9-src.zip/py4j/java_gateway.py", line 690, in start
    self.socket.connect((self.address, self.port))
  File "/usr/lib/python2.7/socket.py", line 224, in meth
    return getattr(self._sock,name)(*args)
error: [Errno 111] Connection refused
ERROR:An error occurred while trying to connect to the Java server
Traceback (most recent call last):
  File "/home/jduarte/Herramientas/spark/python/lib/py4j-0.9-src.zip/py4j/java_gateway.py", line 690, in start
    self.socket.connect((self.address, self.port))
  File "/usr/lib/python2.7/socket.py", line 224, in meth
    return getattr(self._sock,name)(*args)
error: [Errno 111] Connection refused
ERROR:An error occurred while trying to connect to the Java server
Traceback (most recent call last):
  File "/home/jduarte/Herramientas/spark/python/lib/py4j-0.9-src.zip/py4j/java_gateway.py", line 690, in start
    self.socket.connect((self.address, self.port))
  File "/usr/lib/python2.7/socket.py", line 224, in meth
    return getattr(self._sock,name)(*args)
error: [Errno 111] Connection refused
ERROR:An error occurred while trying to connect to the Java server
Traceback (most recent call last):
  File "/home/jduarte/Herramientas/spark/python/lib/py4j-0.9-src.zip/py4j/java_gateway.py", line 690, in start
    self.socket.connect((self.address, self.port))
  File "/usr/lib/python2.7/socket.py", line 224, in meth
    return getattr(self._sock,name)(*args)
error: [Errno 111] Connection refused
ERROR:An error occurred while trying to connect to the Java server
Traceback (most recent call last):
  File "/home/jduarte/Herramientas/spark/python/lib/py4j-0.9-src.zip/py4j/java_gateway.py", line 690, in start
    self.socket.connect((self.address, self.port))
  File "/usr/lib/python2.7/socket.py", line 224, in meth
    return getattr(self._sock,name)(*args)
error: [Errno 111] Connection refused
ERROR:An error occurred while trying to connect to the Java server
Traceback (most recent call last):
  File "/home/jduarte/Herramientas/spark/python/lib/py4j-0.9-src.zip/py4j/java_gateway.py", line 690, in start
    self.socket.connect((self.address, self.port))
  File "/usr/lib/python2.7/socket.py", line 224, in meth
    return getattr(self._sock,name)(*args)
error: [Errno 111] Connection refused
ERROR:An error occurred while trying to connect to the Java server
Traceback (most recent call last):
  File "/home/jduarte/Herramientas/spark/python/lib/py4j-0.9-src.zip/py4j/java_gateway.py", line 690, in start
    self.socket.connect((self.address, self.port))
  File "/usr/lib/python2.7/socket.py", line 224, in meth
    return getattr(self._sock,name)(*args)
error: [Errno 111] Connection refused
ERROR:An error occurred while trying to connect to the Java server
Traceback (most recent call last):
  File "/home/jduarte/Herramientas/spark/python/lib/py4j-0.9-src.zip/py4j/java_gateway.py", line 690, in start
    self.socket.connect((self.address, self.port))
  File "/usr/lib/python2.7/socket.py", line 224, in meth
    return getattr(self._sock,name)(*args)
error: [Errno 111] Connection refused
ERROR:An error occurred while trying to connect to the Java server
Traceback (most recent call last):
  File "/home/jduarte/Herramientas/spark/python/lib/py4j-0.9-src.zip/py4j/java_gateway.py", line 690, in start
    self.socket.connect((self.address, self.port))
  File "/usr/lib/python2.7/socket.py", line 224, in meth
    return getattr(self._sock,name)(*args)
error: [Errno 111] Connection refused
ERROR:An error occurred while trying to connect to the Java server
Traceback (most recent call last):
  File "/home/jduarte/Herramientas/spark/python/lib/py4j-0.9-src.zip/py4j/java_gateway.py", line 690, in start
    self.socket.connect((self.address, self.port))
  File "/usr/lib/python2.7/socket.py", line 224, in meth
    return getattr(self._sock,name)(*args)
error: [Errno 111] Connection refused
ERROR:An error occurred while trying to connect to the Java server
Traceback (most recent call last):
  File "/home/jduarte/Herramientas/spark/python/lib/py4j-0.9-src.zip/py4j/java_gateway.py", line 690, in start
    self.socket.connect((self.address, self.port))
  File "/usr/lib/python2.7/socket.py", line 224, in meth
    return getattr(self._sock,name)(*args)
error: [Errno 111] Connection refused
ERROR:An error occurred while trying to connect to the Java server
Traceback (most recent call last):
  File "/home/jduarte/Herramientas/spark/python/lib/py4j-0.9-src.zip/py4j/java_gateway.py", line 690, in start
    self.socket.connect((self.address, self.port))
  File "/usr/lib/python2.7/socket.py", line 224, in meth
    return getattr(self._sock,name)(*args)
error: [Errno 111] Connection refused
ERROR:An error occurred while trying to connect to the Java server
Traceback (most recent call last):
  File "/home/jduarte/Herramientas/spark/python/lib/py4j-0.9-src.zip/py4j/java_gateway.py", line 690, in start
    self.socket.connect((self.address, self.port))
  File "/usr/lib/python2.7/socket.py", line 224, in meth
    return getattr(self._sock,name)(*args)
error: [Errno 111] Connection refused
ERROR:An error occurred while trying to connect to the Java server
Traceback (most recent call last):
  File "/home/jduarte/Herramientas/spark/python/lib/py4j-0.9-src.zip/py4j/java_gateway.py", line 690, in start
    self.socket.connect((self.address, self.port))
  File "/usr/lib/python2.7/socket.py", line 224, in meth
    return getattr(self._sock,name)(*args)
error: [Errno 111] Connection refused
ERROR:An error occurred while trying to connect to the Java server
Traceback (most recent call last):
  File "/home/jduarte/Herramientas/spark/python/lib/py4j-0.9-src.zip/py4j/java_gateway.py", line 690, in start
    self.socket.connect((self.address, self.port))
  File "/usr/lib/python2.7/socket.py", line 224, in meth
    return getattr(self._sock,name)(*args)
error: [Errno 111] Connection refused
ERROR:An error occurred while trying to connect to the Java server
Traceback (most recent call last):
  File "/home/jduarte/Herramientas/spark/python/lib/py4j-0.9-src.zip/py4j/java_gateway.py", line 690, in start
    self.socket.connect((self.address, self.port))
  File "/usr/lib/python2.7/socket.py", line 224, in meth
    return getattr(self._sock,name)(*args)
error: [Errno 111] Connection refused
ERROR:An error occurred while trying to connect to the Java server
Traceback (most recent call last):
  File "/home/jduarte/Herramientas/spark/python/lib/py4j-0.9-src.zip/py4j/java_gateway.py", line 690, in start
    self.socket.connect((self.address, self.port))
  File "/usr/lib/python2.7/socket.py", line 224, in meth
    return getattr(self._sock,name)(*args)
error: [Errno 111] Connection refused
ERROR:An error occurred while trying to connect to the Java server
Traceback (most recent call last):
  File "/home/jduarte/Herramientas/spark/python/lib/py4j-0.9-src.zip/py4j/java_gateway.py", line 690, in start
    self.socket.connect((self.address, self.port))
  File "/usr/lib/python2.7/socket.py", line 224, in meth
    return getattr(self._sock,name)(*args)
error: [Errno 111] Connection refused
ERROR:An error occurred while trying to connect to the Java server
Traceback (most recent call last):
  File "/home/jduarte/Herramientas/spark/python/lib/py4j-0.9-src.zip/py4j/java_gateway.py", line 690, in start
    self.socket.connect((self.address, self.port))
  File "/usr/lib/python2.7/socket.py", line 224, in meth
    return getattr(self._sock,name)(*args)
error: [Errno 111] Connection refused
ERROR:An error occurred while trying to connect to the Java server
Traceback (most recent call last):
  File "/home/jduarte/Herramientas/spark/python/lib/py4j-0.9-src.zip/py4j/java_gateway.py", line 690, in start
    self.socket.connect((self.address, self.port))
  File "/usr/lib/python2.7/socket.py", line 224, in meth
    return getattr(self._sock,name)(*args)
error: [Errno 111] Connection refused
ERROR:An error occurred while trying to connect to the Java server
Traceback (most recent call last):
  File "/home/jduarte/Herramientas/spark/python/lib/py4j-0.9-src.zip/py4j/java_gateway.py", line 690, in start
    self.socket.connect((self.address, self.port))
  File "/usr/lib/python2.7/socket.py", line 224, in meth
    return getattr(self._sock,name)(*args)
error: [Errno 111] Connection refused
ERROR:An error occurred while trying to connect to the Java server
Traceback (most recent call last):
  File "/home/jduarte/Herramientas/spark/python/lib/py4j-0.9-src.zip/py4j/java_gateway.py", line 690, in start
    self.socket.connect((self.address, self.port))
  File "/usr/lib/python2.7/socket.py", line 224, in meth
    return getattr(self._sock,name)(*args)
error: [Errno 111] Connection refused
ERROR:An error occurred while trying to connect to the Java server
Traceback (most recent call last):
  File "/home/jduarte/Herramientas/spark/python/lib/py4j-0.9-src.zip/py4j/java_gateway.py", line 690, in start
    self.socket.connect((self.address, self.port))
  File "/usr/lib/python2.7/socket.py", line 224, in meth
    return getattr(self._sock,name)(*args)
error: [Errno 111] Connection refused
ERROR:An error occurred while trying to connect to the Java server
Traceback (most recent call last):
  File "/home/jduarte/Herramientas/spark/python/lib/py4j-0.9-src.zip/py4j/java_gateway.py", line 690, in start
    self.socket.connect((self.address, self.port))
  File "/usr/lib/python2.7/socket.py", line 224, in meth
    return getattr(self._sock,name)(*args)
error: [Errno 111] Connection refused
ERROR:An error occurred while trying to connect to the Java server
Traceback (most recent call last):
  File "/home/jduarte/Herramientas/spark/python/lib/py4j-0.9-src.zip/py4j/java_gateway.py", line 690, in start
    self.socket.connect((self.address, self.port))
  File "/usr/lib/python2.7/socket.py", line 224, in meth
    return getattr(self._sock,name)(*args)
error: [Errno 111] Connection refused
ERROR:An error occurred while trying to connect to the Java server
Traceback (most recent call last):
  File "/home/jduarte/Herramientas/spark/python/lib/py4j-0.9-src.zip/py4j/java_gateway.py", line 690, in start
    self.socket.connect((self.address, self.port))
  File "/usr/lib/python2.7/socket.py", line 224, in meth
    return getattr(self._sock,name)(*args)
error: [Errno 111] Connection refused
ERROR:An error occurred while trying to connect to the Java server
Traceback (most recent call last):
  File "/home/jduarte/Herramientas/spark/python/lib/py4j-0.9-src.zip/py4j/java_gateway.py", line 690, in start
    self.socket.connect((self.address, self.port))
  File "/usr/lib/python2.7/socket.py", line 224, in meth
    return getattr(self._sock,name)(*args)
error: [Errno 111] Connection refused
ERROR:An error occurred while trying to connect to the Java server
Traceback (most recent call last):
  File "/home/jduarte/Herramientas/spark/python/lib/py4j-0.9-src.zip/py4j/java_gateway.py", line 690, in start
    self.socket.connect((self.address, self.port))
  File "/usr/lib/python2.7/socket.py", line 224, in meth
    return getattr(self._sock,name)(*args)
error: [Errno 111] Connection refused
ERROR:An error occurred while trying to connect to the Java server
Traceback (most recent call last):
  File "/home/jduarte/Herramientas/spark/python/lib/py4j-0.9-src.zip/py4j/java_gateway.py", line 690, in start
    self.socket.connect((self.address, self.port))
  File "/usr/lib/python2.7/socket.py", line 224, in meth
    return getattr(self._sock,name)(*args)
error: [Errno 111] Connection refused
ERROR:An error occurred while trying to connect to the Java server
Traceback (most recent call last):
  File "/home/jduarte/Herramientas/spark/python/lib/py4j-0.9-src.zip/py4j/java_gateway.py", line 690, in start
    self.socket.connect((self.address, self.port))
  File "/usr/lib/python2.7/socket.py", line 224, in meth
    return getattr(self._sock,name)(*args)
error: [Errno 111] Connection refused
ERROR:An error occurred while trying to connect to the Java server
Traceback (most recent call last):
  File "/home/jduarte/Herramientas/spark/python/lib/py4j-0.9-src.zip/py4j/java_gateway.py", line 690, in start
    self.socket.connect((self.address, self.port))
  File "/usr/lib/python2.7/socket.py", line 224, in meth
    return getattr(self._sock,name)(*args)
error: [Errno 111] Connection refused
ERROR:An error occurred while trying to connect to the Java server
Traceback (most recent call last):
  File "/home/jduarte/Herramientas/spark/python/lib/py4j-0.9-src.zip/py4j/java_gateway.py", line 690, in start
    self.socket.connect((self.address, self.port))
  File "/usr/lib/python2.7/socket.py", line 224, in meth
    return getattr(self._sock,name)(*args)
error: [Errno 111] Connection refused
ERROR:An error occurred while trying to connect to the Java server
Traceback (most recent call last):
  File "/home/jduarte/Herramientas/spark/python/lib/py4j-0.9-src.zip/py4j/java_gateway.py", line 690, in start
    self.socket.connect((self.address, self.port))
  File "/usr/lib/python2.7/socket.py", line 224, in meth
    return getattr(self._sock,name)(*args)
error: [Errno 111] Connection refused
ERROR:An error occurred while trying to connect to the Java server
Traceback (most recent call last):
  File "/home/jduarte/Herramientas/spark/python/lib/py4j-0.9-src.zip/py4j/java_gateway.py", line 690, in start
    self.socket.connect((self.address, self.port))
  File "/usr/lib/python2.7/socket.py", line 224, in meth
    return getattr(self._sock,name)(*args)
error: [Errno 111] Connection refused
ERROR:An error occurred while trying to connect to the Java server
Traceback (most recent call last):
  File "/home/jduarte/Herramientas/spark/python/lib/py4j-0.9-src.zip/py4j/java_gateway.py", line 690, in start
    self.socket.connect((self.address, self.port))
  File "/usr/lib/python2.7/socket.py", line 224, in meth
    return getattr(self._sock,name)(*args)
error: [Errno 111] Connection refused
ERROR:An error occurred while trying to connect to the Java server
Traceback (most recent call last):
  File "/home/jduarte/Herramientas/spark/python/lib/py4j-0.9-src.zip/py4j/java_gateway.py", line 690, in start
    self.socket.connect((self.address, self.port))
  File "/usr/lib/python2.7/socket.py", line 224, in meth
    return getattr(self._sock,name)(*args)
error: [Errno 111] Connection refused
ERROR:An error occurred while trying to connect to the Java server
Traceback (most recent call last):
  File "/home/jduarte/Herramientas/spark/python/lib/py4j-0.9-src.zip/py4j/java_gateway.py", line 690, in start
    self.socket.connect((self.address, self.port))
  File "/usr/lib/python2.7/socket.py", line 224, in meth
    return getattr(self._sock,name)(*args)
error: [Errno 111] Connection refused
ERROR:An error occurred while trying to connect to the Java server
Traceback (most recent call last):
  File "/home/jduarte/Herramientas/spark/python/lib/py4j-0.9-src.zip/py4j/java_gateway.py", line 690, in start
    self.socket.connect((self.address, self.port))
  File "/usr/lib/python2.7/socket.py", line 224, in meth
    return getattr(self._sock,name)(*args)
error: [Errno 111] Connection refused
ERROR:An error occurred while trying to connect to the Java server
Traceback (most recent call last):
  File "/home/jduarte/Herramientas/spark/python/lib/py4j-0.9-src.zip/py4j/java_gateway.py", line 690, in start
    self.socket.connect((self.address, self.port))
  File "/usr/lib/python2.7/socket.py", line 224, in meth
    return getattr(self._sock,name)(*args)
error: [Errno 111] Connection refused
ERROR:An error occurred while trying to connect to the Java server
Traceback (most recent call last):
  File "/home/jduarte/Herramientas/spark/python/lib/py4j-0.9-src.zip/py4j/java_gateway.py", line 690, in start
    self.socket.connect((self.address, self.port))
  File "/usr/lib/python2.7/socket.py", line 224, in meth
    return getattr(self._sock,name)(*args)
error: [Errno 111] Connection refused
ERROR:An error occurred while trying to connect to the Java server
Traceback (most recent call last):
  File "/home/jduarte/Herramientas/spark/python/lib/py4j-0.9-src.zip/py4j/java_gateway.py", line 690, in start
    self.socket.connect((self.address, self.port))
  File "/usr/lib/python2.7/socket.py", line 224, in meth
    return getattr(self._sock,name)(*args)
error: [Errno 111] Connection refused
ERROR:An error occurred while trying to connect to the Java server
Traceback (most recent call last):
  File "/home/jduarte/Herramientas/spark/python/lib/py4j-0.9-src.zip/py4j/java_gateway.py", line 690, in start
    self.socket.connect((self.address, self.port))
  File "/usr/lib/python2.7/socket.py", line 224, in meth
    return getattr(self._sock,name)(*args)
error: [Errno 111] Connection refused
ERROR:An error occurred while trying to connect to the Java server
Traceback (most recent call last):
  File "/home/jduarte/Herramientas/spark/python/lib/py4j-0.9-src.zip/py4j/java_gateway.py", line 690, in start
    self.socket.connect((self.address, self.port))
  File "/usr/lib/python2.7/socket.py", line 224, in meth
    return getattr(self._sock,name)(*args)
error: [Errno 111] Connection refused
ERROR:An error occurred while trying to connect to the Java server
Traceback (most recent call last):
  File "/home/jduarte/Herramientas/spark/python/lib/py4j-0.9-src.zip/py4j/java_gateway.py", line 690, in start
    self.socket.connect((self.address, self.port))
  File "/usr/lib/python2.7/socket.py", line 224, in meth
    return getattr(self._sock,name)(*args)
error: [Errno 111] Connection refused
ERROR:An error occurred while trying to connect to the Java server
Traceback (most recent call last):
  File "/home/jduarte/Herramientas/spark/python/lib/py4j-0.9-src.zip/py4j/java_gateway.py", line 690, in start
    self.socket.connect((self.address, self.port))
  File "/usr/lib/python2.7/socket.py", line 224, in meth
    return getattr(self._sock,name)(*args)
error: [Errno 111] Connection refused
ERROR:An error occurred while trying to connect to the Java server
Traceback (most recent call last):
  File "/home/jduarte/Herramientas/spark/python/lib/py4j-0.9-src.zip/py4j/java_gateway.py", line 690, in start
    self.socket.connect((self.address, self.port))
  File "/usr/lib/python2.7/socket.py", line 224, in meth
    return getattr(self._sock,name)(*args)
error: [Errno 111] Connection refused
ERROR:An error occurred while trying to connect to the Java server
Traceback (most recent call last):
  File "/home/jduarte/Herramientas/spark/python/lib/py4j-0.9-src.zip/py4j/java_gateway.py", line 690, in start
    self.socket.connect((self.address, self.port))
  File "/usr/lib/python2.7/socket.py", line 224, in meth
    return getattr(self._sock,name)(*args)
error: [Errno 111] Connection refused
ERROR:An error occurred while trying to connect to the Java server
Traceback (most recent call last):
  File "/home/jduarte/Herramientas/spark/python/lib/py4j-0.9-src.zip/py4j/java_gateway.py", line 690, in start
    self.socket.connect((self.address, self.port))
  File "/usr/lib/python2.7/socket.py", line 224, in meth
    return getattr(self._sock,name)(*args)
error: [Errno 111] Connection refused
ERROR:An error occurred while trying to connect to the Java server
Traceback (most recent call last):
  File "/home/jduarte/Herramientas/spark/python/lib/py4j-0.9-src.zip/py4j/java_gateway.py", line 690, in start
    self.socket.connect((self.address, self.port))
  File "/usr/lib/python2.7/socket.py", line 224, in meth
    return getattr(self._sock,name)(*args)
error: [Errno 111] Connection refused
ERROR:An error occurred while trying to connect to the Java server
Traceback (most recent call last):
  File "/home/jduarte/Herramientas/spark/python/lib/py4j-0.9-src.zip/py4j/java_gateway.py", line 690, in start
    self.socket.connect((self.address, self.port))
  File "/usr/lib/python2.7/socket.py", line 224, in meth
    return getattr(self._sock,name)(*args)
error: [Errno 111] Connection refused
ERROR:An error occurred while trying to connect to the Java server
Traceback (most recent call last):
  File "/home/jduarte/Herramientas/spark/python/lib/py4j-0.9-src.zip/py4j/java_gateway.py", line 690, in start
    self.socket.connect((self.address, self.port))
  File "/usr/lib/python2.7/socket.py", line 224, in meth
    return getattr(self._sock,name)(*args)
error: [Errno 111] Connection refused
ERROR:An error occurred while trying to connect to the Java server
Traceback (most recent call last):
  File "/home/jduarte/Herramientas/spark/python/lib/py4j-0.9-src.zip/py4j/java_gateway.py", line 690, in start
    self.socket.connect((self.address, self.port))
  File "/usr/lib/python2.7/socket.py", line 224, in meth
    return getattr(self._sock,name)(*args)
error: [Errno 111] Connection refused
ERROR:An error occurred while trying to connect to the Java server
Traceback (most recent call last):
  File "/home/jduarte/Herramientas/spark/python/lib/py4j-0.9-src.zip/py4j/java_gateway.py", line 690, in start
    self.socket.connect((self.address, self.port))
  File "/usr/lib/python2.7/socket.py", line 224, in meth
    return getattr(self._sock,name)(*args)
error: [Errno 111] Connection refused
ERROR:An error occurred while trying to connect to the Java server
Traceback (most recent call last):
  File "/home/jduarte/Herramientas/spark/python/lib/py4j-0.9-src.zip/py4j/java_gateway.py", line 690, in start
    self.socket.connect((self.address, self.port))
  File "/usr/lib/python2.7/socket.py", line 224, in meth
    return getattr(self._sock,name)(*args)
error: [Errno 111] Connection refused
ERROR:An error occurred while trying to connect to the Java server
Traceback (most recent call last):
  File "/home/jduarte/Herramientas/spark/python/lib/py4j-0.9-src.zip/py4j/java_gateway.py", line 690, in start
    self.socket.connect((self.address, self.port))
  File "/usr/lib/python2.7/socket.py", line 224, in meth
    return getattr(self._sock,name)(*args)
error: [Errno 111] Connection refused
ERROR:An error occurred while trying to connect to the Java server
Traceback (most recent call last):
  File "/home/jduarte/Herramientas/spark/python/lib/py4j-0.9-src.zip/py4j/java_gateway.py", line 690, in start
    self.socket.connect((self.address, self.port))
  File "/usr/lib/python2.7/socket.py", line 224, in meth
    return getattr(self._sock,name)(*args)
error: [Errno 111] Connection refused
ERROR:An error occurred while trying to connect to the Java server
Traceback (most recent call last):
  File "/home/jduarte/Herramientas/spark/python/lib/py4j-0.9-src.zip/py4j/java_gateway.py", line 690, in start
    self.socket.connect((self.address, self.port))
  File "/usr/lib/python2.7/socket.py", line 224, in meth
    return getattr(self._sock,name)(*args)
error: [Errno 111] Connection refused
ERROR:An error occurred while trying to connect to the Java server
Traceback (most recent call last):
  File "/home/jduarte/Herramientas/spark/python/lib/py4j-0.9-src.zip/py4j/java_gateway.py", line 690, in start
    self.socket.connect((self.address, self.port))
  File "/usr/lib/python2.7/socket.py", line 224, in meth
    return getattr(self._sock,name)(*args)
error: [Errno 111] Connection refused
ERROR:An error occurred while trying to connect to the Java server
Traceback (most recent call last):
  File "/home/jduarte/Herramientas/spark/python/lib/py4j-0.9-src.zip/py4j/java_gateway.py", line 690, in start
    self.socket.connect((self.address, self.port))
  File "/usr/lib/python2.7/socket.py", line 224, in meth
    return getattr(self._sock,name)(*args)
error: [Errno 111] Connection refused
ERROR:An error occurred while trying to connect to the Java server
Traceback (most recent call last):
  File "/home/jduarte/Herramientas/spark/python/lib/py4j-0.9-src.zip/py4j/java_gateway.py", line 690, in start
    self.socket.connect((self.address, self.port))
  File "/usr/lib/python2.7/socket.py", line 224, in meth
    return getattr(self._sock,name)(*args)
error: [Errno 111] Connection refused
ERROR:An error occurred while trying to connect to the Java server
Traceback (most recent call last):
  File "/home/jduarte/Herramientas/spark/python/lib/py4j-0.9-src.zip/py4j/java_gateway.py", line 690, in start
    self.socket.connect((self.address, self.port))
  File "/usr/lib/python2.7/socket.py", line 224, in meth
    return getattr(self._sock,name)(*args)
error: [Errno 111] Connection refused
ERROR:An error occurred while trying to connect to the Java server
Traceback (most recent call last):
  File "/home/jduarte/Herramientas/spark/python/lib/py4j-0.9-src.zip/py4j/java_gateway.py", line 690, in start
    self.socket.connect((self.address, self.port))
  File "/usr/lib/python2.7/socket.py", line 224, in meth
    return getattr(self._sock,name)(*args)
error: [Errno 111] Connection refused
ERROR:An error occurred while trying to connect to the Java server
Traceback (most recent call last):
  File "/home/jduarte/Herramientas/spark/python/lib/py4j-0.9-src.zip/py4j/java_gateway.py", line 690, in start
    self.socket.connect((self.address, self.port))
  File "/usr/lib/python2.7/socket.py", line 224, in meth
    return getattr(self._sock,name)(*args)
error: [Errno 111] Connection refused
ERROR:An error occurred while trying to connect to the Java server
Traceback (most recent call last):
  File "/home/jduarte/Herramientas/spark/python/lib/py4j-0.9-src.zip/py4j/java_gateway.py", line 690, in start
    self.socket.connect((self.address, self.port))
  File "/usr/lib/python2.7/socket.py", line 224, in meth
    return getattr(self._sock,name)(*args)
error: [Errno 111] Connection refused
ERROR:An error occurred while trying to connect to the Java server
Traceback (most recent call last):
  File "/home/jduarte/Herramientas/spark/python/lib/py4j-0.9-src.zip/py4j/java_gateway.py", line 690, in start
    self.socket.connect((self.address, self.port))
  File "/usr/lib/python2.7/socket.py", line 224, in meth
    return getattr(self._sock,name)(*args)
error: [Errno 111] Connection refused
ERROR:An error occurred while trying to connect to the Java server
Traceback (most recent call last):
  File "/home/jduarte/Herramientas/spark/python/lib/py4j-0.9-src.zip/py4j/java_gateway.py", line 690, in start
    self.socket.connect((self.address, self.port))
  File "/usr/lib/python2.7/socket.py", line 224, in meth
    return getattr(self._sock,name)(*args)
error: [Errno 111] Connection refused
ERROR:An error occurred while trying to connect to the Java server
Traceback (most recent call last):
  File "/home/jduarte/Herramientas/spark/python/lib/py4j-0.9-src.zip/py4j/java_gateway.py", line 690, in start
    self.socket.connect((self.address, self.port))
  File "/usr/lib/python2.7/socket.py", line 224, in meth
    return getattr(self._sock,name)(*args)
error: [Errno 111] Connection refused
ERROR:An error occurred while trying to connect to the Java server
Traceback (most recent call last):
  File "/home/jduarte/Herramientas/spark/python/lib/py4j-0.9-src.zip/py4j/java_gateway.py", line 690, in start
    self.socket.connect((self.address, self.port))
  File "/usr/lib/python2.7/socket.py", line 224, in meth
    return getattr(self._sock,name)(*args)
error: [Errno 111] Connection refused
ERROR:An error occurred while trying to connect to the Java server
Traceback (most recent call last):
  File "/home/jduarte/Herramientas/spark/python/lib/py4j-0.9-src.zip/py4j/java_gateway.py", line 690, in start
    self.socket.connect((self.address, self.port))
  File "/usr/lib/python2.7/socket.py", line 224, in meth
    return getattr(self._sock,name)(*args)
error: [Errno 111] Connection refused
ERROR:An error occurred while trying to connect to the Java server
Traceback (most recent call last):
  File "/home/jduarte/Herramientas/spark/python/lib/py4j-0.9-src.zip/py4j/java_gateway.py", line 690, in start
    self.socket.connect((self.address, self.port))
  File "/usr/lib/python2.7/socket.py", line 224, in meth
    return getattr(self._sock,name)(*args)
error: [Errno 111] Connection refused
ERROR:An error occurred while trying to connect to the Java server
Traceback (most recent call last):
  File "/home/jduarte/Herramientas/spark/python/lib/py4j-0.9-src.zip/py4j/java_gateway.py", line 690, in start
    self.socket.connect((self.address, self.port))
  File "/usr/lib/python2.7/socket.py", line 224, in meth
    return getattr(self._sock,name)(*args)
error: [Errno 111] Connection refused
ERROR:An error occurred while trying to connect to the Java server
Traceback (most recent call last):
  File "/home/jduarte/Herramientas/spark/python/lib/py4j-0.9-src.zip/py4j/java_gateway.py", line 690, in start
    self.socket.connect((self.address, self.port))
  File "/usr/lib/python2.7/socket.py", line 224, in meth
    return getattr(self._sock,name)(*args)
error: [Errno 111] Connection refused
ERROR:An error occurred while trying to connect to the Java server
Traceback (most recent call last):
  File "/home/jduarte/Herramientas/spark/python/lib/py4j-0.9-src.zip/py4j/java_gateway.py", line 690, in start
    self.socket.connect((self.address, self.port))
  File "/usr/lib/python2.7/socket.py", line 224, in meth
    return getattr(self._sock,name)(*args)
error: [Errno 111] Connection refused
ERROR:An error occurred while trying to connect to the Java server
Traceback (most recent call last):
  File "/home/jduarte/Herramientas/spark/python/lib/py4j-0.9-src.zip/py4j/java_gateway.py", line 690, in start
    self.socket.connect((self.address, self.port))
  File "/usr/lib/python2.7/socket.py", line 224, in meth
    return getattr(self._sock,name)(*args)
error: [Errno 111] Connection refused
ERROR:An error occurred while trying to connect to the Java server
Traceback (most recent call last):
  File "/home/jduarte/Herramientas/spark/python/lib/py4j-0.9-src.zip/py4j/java_gateway.py", line 690, in start
    self.socket.connect((self.address, self.port))
  File "/usr/lib/python2.7/socket.py", line 224, in meth
    return getattr(self._sock,name)(*args)
error: [Errno 111] Connection refused
ERROR:An error occurred while trying to connect to the Java server
Traceback (most recent call last):
  File "/home/jduarte/Herramientas/spark/python/lib/py4j-0.9-src.zip/py4j/java_gateway.py", line 690, in start
    self.socket.connect((self.address, self.port))
  File "/usr/lib/python2.7/socket.py", line 224, in meth
    return getattr(self._sock,name)(*args)
error: [Errno 111] Connection refused
ERROR:An error occurred while trying to connect to the Java server
Traceback (most recent call last):
  File "/home/jduarte/Herramientas/spark/python/lib/py4j-0.9-src.zip/py4j/java_gateway.py", line 690, in start
    self.socket.connect((self.address, self.port))
  File "/usr/lib/python2.7/socket.py", line 224, in meth
    return getattr(self._sock,name)(*args)
error: [Errno 111] Connection refused
ERROR:An error occurred while trying to connect to the Java server
Traceback (most recent call last):
  File "/home/jduarte/Herramientas/spark/python/lib/py4j-0.9-src.zip/py4j/java_gateway.py", line 690, in start
    self.socket.connect((self.address, self.port))
  File "/usr/lib/python2.7/socket.py", line 224, in meth
    return getattr(self._sock,name)(*args)
error: [Errno 111] Connection refused
INFO:Calentando motores...
INFO:[13/Jun/2016:19:57:33] ENGINE Bus STARTING
INFO:[13/Jun/2016:19:57:33] ENGINE Started monitor thread '_TimeoutMonitor'.
INFO:[13/Jun/2016:19:57:33] ENGINE Started monitor thread 'Autoreloader'.
INFO:[13/Jun/2016:19:57:33] ENGINE Serving on http://0.0.0.0:5432
INFO:[13/Jun/2016:19:57:33] ENGINE Bus STARTED
INFO:Cargando arhcivos...
INFO:Calculando features para tweets...
INFO:Iniciando calculo de tweets por dia...
INFO:Iniciando calculo de tweets por hora...
INFO:Iniciando exploracion de las fuentes de los tweets...
INFO:Iniciando calculo de diversidad lexicografica...
INFO:Iniciando calculo del promedio de la longuitud de los tweets...
INFO:Iniciando calculo del ratio de respuestas...
INFO:Iniciando calculo del promedio de los hashtags...
INFO:Iniciando calculo del promedio de menciones...
INFO:Iniciando calculo del promedio de palabras por tweet...
INFO:Iniciando calculo del promedio de diversidad de palabras...
INFO:Iniciando calculo del ratio de urls...
INFO:Registrando tablas...
INFO:Join entre tweets...
INFO:Calculando features para usuarios...
INFO:Realizando join de usuarios con tweets...
INFO:Finalizado el join...
INFO:[1.0]
INFO:Cargando arhcivos...
INFO:Calculando features para tweets...
INFO:Iniciando calculo de tweets por dia...
INFO:Iniciando calculo de tweets por hora...
INFO:Iniciando exploracion de las fuentes de los tweets...
INFO:Iniciando calculo de diversidad lexicografica...
INFO:Iniciando calculo del promedio de la longuitud de los tweets...
INFO:Iniciando calculo del ratio de respuestas...
INFO:Iniciando calculo del promedio de los hashtags...
INFO:Iniciando calculo del promedio de menciones...
INFO:Iniciando calculo del promedio de palabras por tweet...
INFO:Iniciando calculo del promedio de diversidad de palabras...
INFO:Iniciando calculo del ratio de urls...
INFO:Registrando tablas...
INFO:Join entre tweets...
INFO:Calculando features para usuarios...
INFO:Realizando join de usuarios con tweets...
INFO:Finalizado el join...
INFO:[0.99]
INFO:Cargando arhcivos...
INFO:Calculando features para tweets...
INFO:Iniciando calculo de tweets por dia...
INFO:Iniciando calculo de tweets por hora...
INFO:Iniciando exploracion de las fuentes de los tweets...
INFO:Iniciando calculo de diversidad lexicografica...
INFO:Iniciando calculo del promedio de la longuitud de los tweets...
INFO:Iniciando calculo del ratio de respuestas...
INFO:Iniciando calculo del promedio de los hashtags...
INFO:Iniciando calculo del promedio de menciones...
INFO:Iniciando calculo del promedio de palabras por tweet...
INFO:Iniciando calculo del promedio de diversidad de palabras...
INFO:Iniciando calculo del ratio de urls...
INFO:Registrando tablas...
INFO:Join entre tweets...
INFO:Calculando features para usuarios...
INFO:Realizando join de usuarios con tweets...
INFO:Finalizado el join...
INFO:[1.05]
INFO:[13/Jun/2016:20:00:56] ENGINE Restarting because /home/jduarte/Workspace/TesisSpark/engine.py changed.
INFO:[13/Jun/2016:20:00:56] ENGINE Stopped thread 'Autoreloader'.
INFO:[13/Jun/2016:20:00:56] ENGINE Bus STOPPING
INFO:[13/Jun/2016:20:00:56] ENGINE HTTP Server cherrypy._cpwsgi_server.CPWSGIServer(('0.0.0.0', 5432)) shut down
INFO:[13/Jun/2016:20:00:56] ENGINE Stopped thread '_TimeoutMonitor'.
INFO:[13/Jun/2016:20:00:56] ENGINE Bus STOPPED
INFO:[13/Jun/2016:20:00:56] ENGINE Bus EXITING
INFO:[13/Jun/2016:20:00:56] ENGINE Bus EXITED
INFO:[13/Jun/2016:20:00:56] ENGINE Waiting for child threads to terminate...
INFO:[13/Jun/2016:20:00:56] ENGINE Re-spawning /home/jduarte/Workspace/TesisSpark/server.py
